Workbook

Sheet ReadMeFirst
A1: Read Me First | C1: Purpose: DataSet for INFO8136 Case Study 2 | D1: Data Set | E1: B
A3: This Excel Workbook was:
B4: Created by: | C4: Sakshi Sandeep Salvi (she/her) Initials: SS
B5: Created for: | C5: Conestoga College BA Program, Courses INFO 8136
B6: Created on: | C6: 45384
B7: Project: | C7: Case Study 2
B8: Possible Consumers of this: | C8: All Section Members of INFO8146
B9: Copyright: | C9: Conestoga College, 2024. All rights reserved
C10: Useage rights granted to registered section members of INFO 8146
A12: Assumptions:
A13: 1 | B13: This WB contains data on 2 Inspection Lines. Little Panda Quality Inspection has more than 2 Inspection Lines
A14: 2 | B14: This WB contains data on 3 Inspected Parts. Little Panda Quality Inspection has more than 400 Inspected Parts
A15: 3 | B15: This WB contains data on 2 Suppliers of Parts To be Inspected (Parts TBI). Little Panda Quality Inspection has more than 2 Suppliers of Parts to Be Inspected
A16: 4 | B16: Little Panda receives parts TBI within 24 hours of their making.
A17: 5 | B17: Suppliers of Parts TBI operate Monday thru Friday at full capacity, and produce about 1/3 of a weekday's output on either Saturday and Sunday
A18: 6 | B18: Assumptions 4 and 5 cause Little Panda's Inspection Loading is the lightest on Sunday and Monday
A19: 7 | B19: Parts that Cannot be Inspected in Shifts 1 and 2 are to be inspected during Shift 3 of the same day,
A20: 9 | B20: LPQI charges for Parts Inspection to the Supplier of the Parts is included in the Suppliers' Other Costs for each Part
A21: 10 | B21: Employees are paid for a Shift of 8 hours, but only do actual work for 7 hours in that shift.
A24: Dimensions to be Analyzed
A25: 1 | B25: LPQI Inspection Line B
A26: 2 | B26: LPQI Shift 3
A27: 3 | B27: Tuesday to Saturday Shifts
A29: Issues to be Explored | C29: see Supplied Videos for more detail
A30: 1 | B30: Inspected Parts - Pass or Fail - Including Costs of Failed Parts
A31: 2 | B31: LPQI Labour Cost and Parts TBI Suppliers' Projected Profits
A32: 3 | B32: LPQI Inspection Line Capacity - Impacted by Varying Parts TBI Deliveries and Varying LPQI Staffing
A34: Mandatory (Expected) Metrics - determined by the Data Analyst Assignment
A35: 1 | B35: Day + Shift + Inspection Line - Over/Under
A36: 2 | B36: Day + Shift + Inspection Line - Pass %
A37: 3 | B37: Day + Shift + Inspection Line - Possible Supplier Profit
A38: 4 | B38: Day + Shift + Inspection Line - Total LPQI Labour $
A39: 5 | B39: Day + Shift + Inspection Line - LPQI Inspect Labour $ per Part Inspected
A41: Data Analyst Assignment
B42: Each Analyst will be Assigned a Combination of each of the 3 Dimensions listed above, and one of the Issues to be Explored
B43: For example, a DA might be assigned: Inspection Line B, Shift 2, Sunday+Monday Shifts, and LPQI Inpsection Line Capacity
B44: The assignment will be done by the Section's Faculty
A46: Document History
A47: ID | B47: Updated by and on: | C47: Published on: | D47: Reason(s):
A48: 1 | B48: Sakshi Salvi on July 16th | C48: 45854 | D48: Update the ReadMeFirst Sheet and perform calculations on the Inspect DM Sheet.
...

Sheet Needs+Insights
A1: Client Needs and Executive Summary – INFO8136 Case Study 2
A3: Client Need and Insight
A4: Inspection Line | B4: B
A5: Shift | B5: 3
A6: Days of Week | B6: Tuesday to Saturday
A7: Issue | B7: 4 Stranded TBI Parts on Sun, Mon Shift 3 - Inspect Line Actuals and Capacity on Sun, Mon Day Shifts, Tues to Sat Night Shift #3s
A8: Dataset | B8: 8136 CS2 Dataset B.xlsx
A10: Executive Summary
A11: The client faces consistent inspection backlogs that directly impact supplier profits. Despite a fixed capacity, certain shifts — particularly Shift 3, show disproportionately high uninspected volumes, indicating missed inspection windows and inefficiencies in part handling or prioritization. Data analysis across dates, shifts, and product types revealed that the backlog is not only recurring but also associated with high-value parts. Without dynamic workload balancing or a priority inspection queue, profits are lost due to parts never being inspected at all.
A13: Key Findings:
A14: 1. High-profit parts are consistently missed due to ineffective prioritization in Shift 3.
A15: 2. Stranded parts accumulate throughout the week due to non-responsive capacity planning.
A16: 3. Delivery inconsistencies and absence of profit-driven queueing lead to inspection delays.
A17: 4. The inspection line fails to adapt dynamically to daily workload and part value.
A19: List of Four Metric Datasets from 5 Why’s
A20: Weekly uninspected profit $ by product type
A21: Weekly count of uninspected parts by product type
A22: Daily stranded profit $ by date and product type
A23: Daily count of uninspected parts by product type
... A33: The daily capacity remained flat while received volumes fluctuated. Without a priority queue system, inspection often ignored the highest-value parts, especially when volumes exceeded capacity. The result was predictable and preventable backlogs.

Sheet 5 Why's
A1: 5 Why's
A3: Issue | B3: 4 Stranded TBI Parts on Sun, Mon Shift 3 - Inspect Line Actuals and Capacity on Sun, Mon Day Shifts, Tues to Sat Night Shift #3s
A4: Focus | B4: Line B, Shift 3, Days 3-7
A6: Level 0 | B6: Weekly Stranded Parts | C6: Not Inspected Parts $ Profit Value by Product Type by Part by Week (7 days) For Tues to Saturday Shift #3
A7: Level 1 | B7: Reverse Level 0 | C7: Not Inspected Parts Count by Product Type by Part by Week (7 days) For Tues to Saturday Shift #3
A8: Level 2 | B8: Daily Stranded Parts | C8: Not Inspected Parts $ Profit Value by Product Type by Part by Date For Tues to Saturday Shift #3
A9: Level 3 | B9: Reverse Level 2 | C9: Not Inspected Parts Count by Product Type by Part by Date For Tues to Saturday Shift #3s
A10: Level 4 | B10: Capacity | C10: Capacity-utilization summary which compares daily capacity vs received vs stranded parts
A12: Level 0 | B12: Weekly Stranded Parts
A13: Question | B13: Why are Product Types' Profits on Parts not maximum?
A14: Answers | B14: 1. Parts that are not inspected during the first day never get inspected. 2. Inspectors are not motivated to finish all of their work. 3. The Porters are delivering parts TBI to the wrong lines.
A17: Chosen Answer | B17: 1. Parts that are not inspected during the first day never get inspected.
A18: Dataset | B18: Line B Dataset
A19: What’s in it | B19: Data Source: Line B Dataset sheet Columns Used: Week, LineB-ProdType, Shift, and Not Inspected Profit $ Calculation Formula: Not Inspected Profit $ = Not Inspected × Possible Supplier Profit Filters Applied: Line B inspection, Day of Week = 3 to 7 (Tuesday to Saturday), all three shifts included for comparison.
A20: Visualization | B20: Clustered column chart → Product Type vs Not Inspected Profit $
A22: Level 1 | B22: Reverse Level 0
A23: Question | B23: Why are the counts of stranded parts high each week?
A24: Answers | B24: 1. High-profit parts are missed due to inefficient prioritization. 2. Week-start backlog continues unchecked throughout the week. 3. Late-arriving parts miss inspection cutoff times.
A27: Chosen Answer | B27: 1. High-profit parts are missed due to inefficient prioritization.
A28: Dataset | B28: Line B Dataset
... A60: Visualization | B60: Combo chart → Day vs Capacity vs Received vs Received Inspected vs Stranded (Not Inspected)

Sheet Line B Dataset
A1: Line B Dataset Filtered - This sheet was created to perform pivot table and visualizations for Level 0-Level 3
A2: Column for Week number was added (E)
A3: Column for Not Inspected Profit $ was added (Y)
G6: Line B Inspection Data | AE6: 1 | AF6: 4 | AG6: 3 | AL6: 5 | AM6: 6
B7: InspectDataID | C7: Date | D7: Day of Week | E7: Week | F7: Shift | G7: LineB-ProdType | H7: Received | I7: Received Inspected | J7: Leftover Inspected | K7: Capacity | L7: Not Inspected | M7: Left From Day Shift for 3rd Shift | N7: Inspect Pass | O7: Over/Under | P7: Pass% | Q7: Supplier Income per Part | R7: Supplier Cost to Make | S7: Supplier Other Cost | T7: Supplier Cost per Part | U7: Possible Supplier Income | V7: Supplier Cost of Parts | W7: Possible Supplier Profit | X7: Supplier Cost of Bad Parts | Y7: Not Inspected Profit $ | Z7: Inspectors | AA7: Inspectors | AB7: Training | AC7: Regular | AD7: Casual | AE7: Training $ | AF7: Regular $ | AG7: Casual $ | AH7: Total Line B $ | AI7: Inspect Labour $ per Part | AJ7: Team Lead | AK7: Shipper/Receiver/Porter | AL7: Team Lead $ | AM7: =AK7& " $" -> Shipper/Receiver/Porter $ | AN7: All Total Labour $
B8: 160 | C8: 45323 | D8: =WEEKDAY(C8, 1) -> 5 | E8: =_xlfn.ISOWEEKNUM(C8) -> 5 | F8: 1 | G8: 105 | H8: 194 | I8: 194 | J8: 0 | K8: 216 | L8: 0 | M8: 0 | N8: 180 | O8: =H8-I8 -> 0 | P8: =N8/I8 -> 0.92783505 | Q8: =VLOOKUP($G$8, 'Other Lists'!$B$13:$H$15, 7, FALSE) -> 184 | R8: =VLOOKUP($G$8, 'Other Lists'!$B$13:$F$15, 5, FALSE) -> 129 | S8: =VLOOKUP($G$8, 'Other Lists'!$B$13:$G$15, 6, FALSE) -> 36 | T8: =R8+S8 -> 165 | U8: =VLOOKUP($G$8, 'Other Lists'!$B$13:$H$15, 7, FALSE) *N8 -> 33120 | V8: =T8*I8 -> 32010 | W8: =U8-V8 -> 1110 | X8: =(I8-N8)*Q8 -> 2576 | Y8: =L8*W8 -> 0 | Z8: 8 | AA8: 8 | AB8: 0 | AC8: 4 | AD8: =AA8-AB8-AC8-AJ8 -> 2 | AE8: =VLOOKUP($AE$6, 'Other Lists'!$B$27:$H$32, 7, FALSE) *AB8*8 -> 0 | AF8: =VLOOKUP($AF$6, 'Other Lists'!$B$27:$H$32, 7, FALSE) * AC8 * 8 -> 1123.2 | AG8: =VLOOKUP($AG$6, 'Other Lists'!$B$27:$H$32, 7, FALSE) * AD8 * 8 -> 518.4 | AH8: =SUM($AE$8:$AG$8) -> 1641.6 | AI8: =AH8/I8 -> 8.4618557 | AJ8: 2 | AK8: 2 | AL8: =VLOOKUP($AL$6, 'Other Lists'!$B$27:$H$32, 7, FALSE) * AJ8 * 8 -> 648 | AM8: =VLOOKUP($AM$6, 'Other Lists'!$B$27:$H$32, 7, FALSE) * AK8 * 8 -> 648 | AN8: =SUM(AH8,AL8,AM8) -> 2937.6
B9: 161 | C9: 45324 | D9: =WEEKDAY(C9, 1) -> 6 | E9: =_xlfn.ISOWEEKNUM(C9) -> 5 | F9: 1 | G9: 105 | H9: 213 | I9: 205 | J9: 0 | K9: 216 | L9: 8 | M9: 0 | N9: 190 | O9: =H9-I9 -> 8 | P9: =N9/I9 -> 0.92682927 | Q9: =VLOOKUP($G$8, 'Other Lists'!$B$13:$H$15, 7, FALSE) -> 184 | R9: =VLOOKUP($G$8, 'Other Lists'!$B$13:$F$15, 5, FALSE) -> 129 | S9: =VLOOKUP($G$8, 'Other Lists'!$B$13:$G$15, 6, FALSE) -> 36 | T9: =R9+S9 -> 165 | U9: =VLOOKUP($G$8, 'Other Lists'!$B$13:$H$15, 7, FALSE) *N9 -> 34960 | V9: =T9*I9 -> 33825 | W9: =U9-V9 -> 1135 | X9: =(I9-N9)*Q9 -> 2760 | Y9: =L9*W9 -> 9080 | Z9: 8 | AA9: 8 | AB9: 0 | AC9: 4 | AD9: =AA9-AB9-AC9-AJ9 -> 2 | AE9: =VLOOKUP($AE$6, 'Other Lists'!$B$27:$H$32, 7, FALSE) *AB9*8 -> 0 | AF9: =VLOOKUP($AF$6, 'Other Lists'!$B$27:$H$32, 7, FALSE) * AC9 * 8 -> 1123.2 | AG9: =VLOOKUP($AG$6, 'Other Lists'!$B$27:$H$32, 7, FALSE) * AD9 * 8 -> 518.4 | AH9: =SUM($AE$8:$AG$8) -> 1641.6 | AI9: =AH9/I9 -> 8.0078049 | AJ9: 2 | AK9: 2 | AL9: =VLOOKUP($AL$6, 'Other Lists'!$B$27:$H$32, 7, FALSE) * AJ9 * 8 -> 648 | AM9: =VLOOKUP($AM$6, 'Other Lists'!$B$27:$H$32, 7, FALSE) * AK9 * 8 -> 648 | AN9: =SUM(AH9,AL9,AM9) -> 2937.6
B10: 162 | C10: 45325 | D10: =WEEKDAY(C10, 1) -> 7 | E10: =_xlfn.ISOWEEKNUM(C10) -> 5 | F10: 1 | G10: 105 | H10: 259 | I10: 218 | J10: 0 | K10: 216 | L10: 41 | M10: 0 | N10: 209 | O10: =H10-I10 -> 41 | P10: =N10/I10 -> 0.9587156 | Q10: =VLOOKUP($G$8, 'Other Lists'!$B$13:$H$15, 7, FALSE) -> 184 | R10: =VLOOKUP($G$8, 'Other Lists'!$B$13:$F$15, 5, FALSE) -> 129 | S10: =VLOOKUP($G$8, 'Other Lists'!$B$13:$G$15, 6, FALSE) -> 36 | T10: =R10+S10 -> 165 | U10: =VLOOKUP($G$8, 'Other Lists'!$B$13:$H$15, 7, FALSE) *N10 -> 38456 | V10: =T10*I10 -> 35970 | W10: =U10-V10 -> 2486 | X10: =(I10-N10)*Q10 -> 1656 | Y10: =L10*W10 -> 101926 | Z10: 8 | AA10: 8 | AB10: 1 | AC10: 3 | AD10: =AA10-AB10-AC10-AJ10 -> 3 | AE10: =VLOOKUP($AE$6, 'Other Lists'!$B$27:$H$32, 7, FALSE) *AB10*8 -> 194.4 | AF10: =VLOOKUP($AF$6, 'Other Lists'!$B$27:$H$32, 7, FALSE) * AC10 * 8 -> 842.4 | AG10: =VLOOKUP($AG$6, 'Other Lists'!$B$27:$H$32, 7, FALSE) * AD10 * 8 -> 777.6 | AH10: =SUM($AE$8:$AG$8) -> 1641.6 | AI10: =AH10/I10 -> 7.5302752 | AJ10: 1 | AK10: 2 | AL10: =VLOOKUP($AL$6, 'Other Lists'!$B$27:$H$32, 7, FALSE) * AJ10 * 8 -> 324 | AM10: =VLOOKUP($AM$6, 'Other Lists'!$B$27:$H$32, 7, FALSE) * AK10 * 8 -> 648 | AN10: =SUM(AH10,AL10,AM10) -> 2613.6
B11: 165 | C11: 45328 | D11: =WEEKDAY(C11, 1) -> 3 | E11: =_xlfn.ISOWEEKNUM(C11) -> 6 | F11: 1 | G11: 105 | H11: 181 | I11: 181 | J11: 0 | K11: 216 | L11: 0 | M11: 0 | N11: 171 | O11: =H11-I11 -> 0 | P11: =N11/I11 -> 0.94475138 | Q11: =VLOOKUP($G$8, 'Other Lists'!$B$13:$H$15, 7, FALSE) -> 184 | R11: =VLOOKUP($G$8, 'Other Lists'!$B$13:$F$15, 5, FALSE) -> 129 | S11: =VLOOKUP($G$8, 'Other Lists'!$B$13:$G$15, 6, FALSE) -> 36 | T11: =R11+S11 -> 165 | U11: =VLOOKUP($G$8, 'Other Lists'!$B$13:$H$15, 7, FALSE) *N11 -> 31464 | V11: =T11*I11 -> 29865 | W11: =U11-V11 -> 1599 | X11: =(I11-N11)*Q11 -> 1840 | Y11: =L11*W11 -> 0 | Z11: 8 | AA11: 8 | AB11: 0 | AC11: 3 | AD11: =AA11-AB11-AC11-AJ11 -> 3 | AE11: =VLOOKUP($AE$6, 'Other Lists'!$B$27:$H$32, 7, FALSE) *AB11*8 -> 0 | AF11: =VLOOKUP($AF$6, 'Other Lists'!$B$27:$H$32, 7, FALSE) * AC11 * 8 -> 842.4 | AG11: =VLOOKUP($AG$6, 'Other Lists'!$B$27:$H$32, 7, FALSE) * AD11 * 8 -> 777.6 | AH11: =SUM($AE$8:$AG$8) -> 1641.6 | AI11: =AH11/I11 -> 9.0696133 | AJ11: 2 | AK11: 2 | AL11: =VLOOKUP($AL$6, 'Other Lists'!$B$27:$H$32, 7, FALSE) * AJ11 * 8 -> 648 | AM11: =VLOOKUP($AM$6, 'Other Lists'!$B$27:$H$32, 7, FALSE) * AK11 * 8 -> 648 | AN11: =SUM(AH11,AL11,AM11) -> 2937.6
B12: 166 | C12: 45329 | D12: =WEEKDAY(C12, 1) -> 4 | E12: =_xlfn.ISOWEEKNUM(C12) -> 6 | F12: 1 | G12: 105 | H12: 233 | I12: 207 | J12: 0 | K12: 216 | L12: 26 | M12: 0 | N12: 192 | O12: =H12-I12 -> 26 | P12: =N12/I12 -> 0.92753623 | Q12: =VLOOKUP($G$8, 'Other Lists'!$B$13:$H$15, 7, FALSE) -> 184 | R12: =VLOOKUP($G$8, 'Other Lists'!$B$13:$F$15, 5, FALSE) -> 129 | S12: =VLOOKUP($G$8, 'Other Lists'!$B$13:$G$15, 6, FALSE) -> 36 | T12: =R12+S12 -> 165 | U12: =VLOOKUP($G$8, 'Other Lists'!$B$13:$H$15, 7, FALSE) *N12 -> 35328 | V12: =T12*I12 -> 34155 | W12: =U12-V12 -> 1173 | X12: =(I12-N12)*Q12 -> 2760 | Y12: =L12*W12 -> 30498 | Z12: 8 | AA12: 8 | AB12: 0 | AC12: 4 | AD12: =AA12-AB12-AC12-AJ12 -> 2 | AE12: =VLOOKUP($AE$6, 'Other Lists'!$B$27:$H$32, 7, FALSE) *AB12*8 -> 0 | AF12: =VLOOKUP($AF$6, 'Other Lists'!$B$27:$H$32, 7, FALSE) * AC12 * 8 -> 1123.2 | AG12: =VLOOKUP($AG$6, 'Other Lists'!$B$27:$H$32, 7, FALSE) * AD12 * 8 -> 518.4 | AH12: =SUM($AE$8:$AG$8) -> 1641.6 | AI12: =AH12/I12 -> 7.9304348 | AJ12: 2 | AK12: 2 | AL12: =VLOOKUP($AL$6, 'Other Lists'!$B$27:$H$32, 7, FALSE) * AJ12 * 8 -> 648 | AM12: =VLOOKUP($AM$6, 'Other Lists'!$B$27:$H$32, 7, FALSE) * AK12 * 8 -> 648 | AN12: =SUM(AH12,AL12,AM12) -> 2937.6
B13: 167 | C13: 45330 | D13: =WEEKDAY(C13, 1) -> 5 | E13: =_xlfn.ISOWEEKNUM(C13) -> 6 | F13: 1 | G13: 105 | H13: 203 | I13: 186 | J13: 0 | K13: 216 | L13: 17 | M13: 0 | N13: 182 | O13: =H13-I13 -> 17 | P13: =N13/I13 -> 0.97849462 | Q13: =VLOOKUP($G$8, 'Other Lists'!$B$13:$H$15, 7, FALSE) -> 184 | R13: =VLOOKUP($G$8, 'Other Lists'!$B$13:$F$15, 5, FALSE) -> 129 | S13: =VLOOKUP($G$8, 'Other Lists'!$B$13:$G$15, 6, FALSE) -> 36 | T13: =R13+S13 -> 165 | U13: =VLOOKUP($G$8, 'Other Lists'!$B$13:$H$15, 7, FALSE) *N13 -> 33488 | V13: =T13*I13 -> 30690 | W13: =U13-V13 -> 2798 | X13: =(I13-N13)*Q13 -> 736 | Y13: =L13*W13 -> 47566 | Z13: 8 | AA13: 7 | AB13: 1 | AC13: 3 | AD13: =AA13-AB13-AC13-AJ13 -> 1 | AE13: =VLOOKUP($AE$6, 'Other Lists'!$B$27:$H$32, 7, FALSE) *AB13*8 -> 194.4 | AF13: =VLOOKUP($AF$6, 'Other Lists'!$B$27:$H$32, 7, FALSE) * AC13 * 8 -> 842.4 | AG13: =VLOOKUP($AG$6, 'Other Lists'!$B$27:$H$32, 7, FALSE) * AD13 * 8 -> 259.2 | AH13: =SUM($AE$8:$AG$8) -> 1641.6 | AI13: =AH13/I13 -> 8.8258065 | AJ13: 2 | AK13: 2 | AL13: =VLOOKUP($AL$6, 'Other Lists'!$B$27:$H$32, 7, FALSE) * AJ13 * 8 -> 648 | AM13: =VLOOKUP($AM$6, 'Other Lists'!$B$27:$H$32, 7, FALSE) * AK13 * 8 -> 648 | AN13: =SUM(AH13,AL13,AM13) -> 2937.6
B14: 168 | C14: 45331 | D14: =WEEKDAY(C14, 1) -> 6 | E14: =_xlfn.ISOWEEKNUM(C14) -> 6 | F14: 1 | G14: 105 | H14: 216 | I14: 211 | J14: 0 | K14: 216 | L14: 5 | M14: 0 | N14: 202 | O14: =H14-I14 -> 5 | P14: =N14/I14 -> 0.95734597 | Q14: =VLOOKUP($G$8, 'Other Lists'!$B$13:$H$15, 7, FALSE) -> 184 | R14: =VLOOKUP($G$8, 'Other Lists'!$B$13:$F$15, 5, FALSE) -> 129 | S14: =VLOOKUP($G$8, 'Other Lists'!$B$13:$G$15, 6, FALSE) -> 36 | T14: =R14+S14 -> 165 | U14: =VLOOKUP($G$8, 'Other Lists'!$B$13:$H$15, 7, FALSE) *N14 -> 37168 | V14: =T14*I14 -> 34815 | W14: =U14-V14 -> 2353 | X14: =(I14-N14)*Q14 -> 1656 | Y14: =L14*W14 -> 11765 | Z14: 8 | AA14: 8 | AB14: 0 | AC14: 4 | AD14: =AA14-AB14-AC14-AJ14 -> 2 | AE14: =VLOOKUP($AE$6, 'Other Lists'!$B$27:$H$32, 7, FALSE) *AB14*8 -> 0 | AF14: =VLOOKUP($AF$6, 'Other Lists'!$B$27:$H$32, 7, FALSE) * AC14 * 8 -> 1123.2 | AG14: =VLOOKUP($AG$6, 'Other Lists'!$B$27:$H$32, 7, FALSE) * AD14 * 8 -> 518.4 | AH14: =SUM($AE$8:$AG$8) -> 1641.6 | AI14: =AH14/I14 -> 7.7800948 | AJ14: 2 | AK14: 2 | AL14: =VLOOKUP($AL$6, 'Other Lists'!$B$27:$H$32, 7, FALSE) * AJ14 * 8 -> 648 | AM14: =VLOOKUP($AM$6, 'Other Lists'!$B$27:$H$32, 7, FALSE) * AK14 * 8 -> 648 | AN14: =SUM(AH14,AL14,AM14) -> 2937.6
B15: 169 | C15: 45332 | D15: =WEEKDAY(C15, 1) -> 7 | E15: =_xlfn.ISOWEEKNUM(C15) -> 6 | F15: 1 | G15: 105 | H15: 194 | I15: 170 | J15: 0 | K15: 216 | L15: 24 | M15: 0 | N15: 164 | O15: =H15-I15 -> 24 | P15: =N15/I15 -> 0.96470588 | Q15: =VLOOKUP($G$8, 'Other Lists'!$B$13:$H$15, 7, FALSE) -> 184 | R15: =VLOOKUP($G$8, 'Other Lists'!$B$13:$F$15, 5, FALSE) -> 129 | S15: =VLOOKUP($G$8, 'Other Lists'!$B$13:$G$15, 6, FALSE) -> 36 | T15: =R15+S15 -> 165 | U15: =VLOOKUP($G$8, 'Other Lists'!$B$13:$H$15, 7, FALSE) *N15 -> 30176 | V15: =T15*I15 -> 28050 | W15: =U15-V15 -> 2126 | X15: =(I15-N15)*Q15 -> 1104 | Y15: =L15*W15 -> 51024 | Z15: 8 | AA15: 7 | AB15: 1 | AC15: 3 | AD15: =AA15-AB15-AC15-AJ15 -> 1 | AE15: =VLOOKUP($AE$6, 'Other Lists'!$B$27:$H$32, 7, FALSE) *AB15*8 -> 194.4 | AF15: =VLOOKUP($AF$6, 'Other Lists'!$B$27:$H$32, 7, FALSE) * AC15 * 8 -> 842.4 | AG15: =VLOOKUP($AG$6, 'Other Lists'!$B$27:$H$32, 7, FALSE) * AD15 * 8 -> 259.2 | AH15: =SUM($AE$8:$AG$8) -> 1641.6 | AI15: =AH15/I15 -> 9.6564706 | AJ15: 2 | AK15: 2 | AL15: =VLOOKUP($AL$6, 'Other Lists'!$B$27:$H$32, 7, FALSE) * AJ15 * 8 -> 648 | AM15: =VLOOKUP($AM$6, 'Other Lists'!$B$27:$H$32, 7, FALSE) * AK15 * 8 -> 648 | AN15: =SUM(AH15,AL15,AM15) -> 2937.6
B16: 172 | C16: 45335 | D16: =WEEKDAY(C16, 1) -> 3 | E16: =_xlfn.ISOWEEKNUM(C16) -> 7 | F16: 1 | G16: 105 | H16: 209 | I16: 207 | J16: 0 | K16: 216 | L16: 2 | M16: 0 | N16: 200 | O16: =H16-I16 -> 2 | P16: =N16/I16 -> 0.96618357 | Q16: =VLOOKUP($G$8, 'Other Lists'!$B$13:$H$15, 7, FALSE) -> 184 | R16: =VLOOKUP($G$8, 'Other Lists'!$B$13:$F$15, 5, FALSE) -> 129 | S16: =VLOOKUP($G$8, 'Other Lists'!$B$13:$G$15, 6, FALSE) -> 36 | T16: =R16+S16 -> 165 | U16: =VLOOKUP($G$8, 'Other Lists'!$B$13:$H$15, 7, FALSE) *N16 -> 36800 | V16: =T16*I16 -> 34155 | W16: =U16-V16 -> 2645 | X16: =(I16-N16)*Q16 -> 1288 | Y16: =L16*W16 -> 5290 | Z16: 8 | AA16: 8 | AB16: 0 | AC16: 3 | AD16: =AA16-AB16-AC16-AJ16 -> 3 | AE16: =VLOOKUP($AE$6, 'Other Lists'!$B$27:$H$32, 7, FALSE) *AB16*8 -> 0 | AF16: =VLOOKUP($AF$6, 'Other Lists'!$B$27:$H$32, 7, FALSE) * AC16 * 8 -> 842.4 | AG16: =VLOOKUP($AG$6, 'Other Lists'!$B$27:$H$32, 7, FALSE) * AD16 * 8 -> 777.6 | AH16: =SUM($AE$8:$AG$8) -> 1641.6 | AI16: =AH16/I16 -> 7.9304348 | AJ16: 2 | AK16: 2 | AL16: =VLOOKUP($AL$6, 'Other Lists'!$B$27:$H$32, 7, FALSE) * AJ16 * 8 -> 648 | AM16: =VLOOKUP($AM$6, 'Other Lists'!$B$27:$H$32, 7, FALSE) * AK16 * 8 -> 648 | AN16: =SUM(AH16,AL16,AM16) -> 2937.6
B17: 173 | C17: 45336 | D17: =WEEKDAY(C17, 1) -> 4 | E17: =_xlfn.ISOWEEKNUM(C17) -> 7 | F17: 1 | G17: 105 | H17: 203 | I17: 203 | J17: 0 | K17: 216 | L17: 0 | M17: 0 | N17: 188 | O17: =H17-I17 -> 0 | P17: =N17/I17 -> 0.92610837 | Q17: =VLOOKUP($G$8, 'Other Lists'!$B$13:$H$15, 7, FALSE) -> 184 | R17: =VLOOKUP($G$8, 'Other Lists'!$B$13:$F$15, 5, FALSE) -> 129 | S17: =VLOOKUP($G$8, 'Other Lists'!$B$13:$G$15, 6, FALSE) -> 36 | T17: =R17+S17 -> 165 | U17: =VLOOKUP($G$8, 'Other Lists'!$B$13:$H$15, 7, FALSE) *N17 -> 34592 | V17: =T17*I17 -> 33495 | W17: =U17-V17 -> 1097 | X17: =(I17-N17)*Q17 -> 2760 | Y17: =L17*W17 -> 0 | Z17: 8 | AA17: 8 | AB17: 0 | AC17: 3 | AD17: =AA17-AB17-AC17-AJ17 -> 3 | AE17: =VLOOKUP($AE$6, 'Other Lists'!$B$27:$H$32, 7, FALSE) *AB17*8 -> 0 | AF17: =VLOOKUP($AF$6, 'Other Lists'!$B$27:$H$32, 7, FALSE) * AC17 * 8 -> 842.4 | AG17: =VLOOKUP($AG$6, 'Other Lists'!$B$27:$H$32, 7, FALSE) * AD17 * 8 -> 777.6 | AH17: =SUM($AE$8:$AG$8) -> 1641.6 | AI17: =AH17/I17 -> 8.0866995 | AJ17: 2 | AK17: 2 | AL17: =VLOOKUP($AL$6, 'Other Lists'!$B$27:$H$32, 7, FALSE) * AJ17 * 8 -> 648 | AM17: =VLOOKUP($AM$6, 'Other Lists'!$B$27:$H$32, 7, FALSE) * AK17 * 8 -> 648 | AN17: =SUM(AH17,AL17,AM17) -> 2937.6
B18: 174 | C18: 45337 | D18: =WEEKDAY(C18, 1) -> 5 | E18: =_xlfn.ISOWEEKNUM(C18) -> 7 | F18: 1 | G18: 105 | H18: 187 | I18: 187 | J18: 0 | K18: 216 | L18: 0 | M18: 0 | N18: 181 | O18: =H18-I18 -> 0 | P18: =N18/I18 -> 0.96791444 | Q18: =VLOOKUP($G$8, 'Other Lists'!$B$13:$H$15, 7, FALSE) -> 184 | R18: =VLOOKUP($G$8, 'Other Lists'!$B$13:$F$15, 5, FALSE) -> 129 | S18: =VLOOKUP($G$8, 'Other Lists'!$B$13:$G$15, 6, FALSE) -> 36 | T18: =R18+S18 -> 165 | U18: =VLOOKUP($G$8, 'Other Lists'!$B$13:$H$15, 7, FALSE) *N18 -> 33304 | V18: =T18*I18 -> 30855 | W18: =U18-V18 -> 2449 | X18: =(I18-N18)*Q18 -> 1104 | Y18: =L18*W18 -> 0 | Z18: 8 | AA18: 8 | AB18: 1 | AC18: 4 | AD18: =AA18-AB18-AC18-AJ18 -> 1 | AE18: =VLOOKUP($AE$6, 'Other Lists'!$B$27:$H$32, 7, FALSE) *AB18*8 -> 194.4 | AF18: =VLOOKUP($AF$6, 'Other Lists'!$B$27:$H$32, 7, FALSE) * AC18 * 8 -> 1123.2 | AG18: =VLOOKUP($AG$6, 'Other Lists'!$B$27:$H$32, 7, FALSE) * AD18 * 8 -> 259.2 | AH18: =SUM($AE$8:$AG$8) -> 1641.6 | AI18: =AH18/I18 -> 8.7786096 | AJ18: 2 | AK18: 2 | AL18: =VLOOKUP($AL$6, 'Other Lists'!$B$27:$H$32, 7, FALSE) * AJ18 * 8 -> 648 | AM18: =VLOOKUP($AM$6, 'Other Lists'!$B$27:$H$32, 7, FALSE) * AK18 * 8 -> 648 | AN18: =SUM(AH18,AL18,AM18) -> 2937.6
B19: 175 | C19: 45338 | D19: =WEEKDAY(C19, 1) -> 6 | E19: =_xlfn.ISOWEEKNUM(C19) -> 7 | F19: 1 | G19: 105 | H19: 177 | I19: 177 | J19: 0 | K19: 216 | L19: 0 | M19: 0 | N19: 171 | O19: =H19-I19 -> 0 | P19: =N19/I19 -> 0.96610169 | Q19: =VLOOKUP($G$8, 'Other Lists'!$B$13:$H$15, 7, FALSE) -> 184 | R19: =VLOOKUP($G$8, 'Other Lists'!$B$13:$F$15, 5, FALSE) -> 129 | S19: =VLOOKUP($G$8, 'Other Lists'!$B$13:$G$15, 6, FALSE) -> 36 | T19: =R19+S19 -> 165 | U19: =VLOOKUP($G$8, 'Other Lists'!$B$13:$H$15, 7, FALSE) *N19 -> 31464 | V19: =T19*I19 -> 29205 | W19: =U19-V19 -> 2259 | X19: =(I19-N19)*Q19 -> 1104 | Y19: =L19*W19 -> 0 | Z19: 8 | AA19: 8 | AB19: 0 | AC19: 4 | AD19: =AA19-AB19-AC19-AJ19 -> 2 | AE19: =VLOOKUP($AE$6, 'Other Lists'!$B$27:$H$32, 7, FALSE) *AB19*8 -> 0 | AF19: =VLOOKUP($AF$6, 'Other Lists'!$B$27:$H$32, 7, FALSE) * AC19 * 8 -> 1123.2 | AG19: =VLOOKUP($AG$6, 'Other Lists'!$B$27:$H$32, 7, FALSE) * AD19 * 8 -> 518.4 | AH19: =SUM($AE$8:$AG$8) -> 1641.6 | AI19: =AH19/I19 -> 9.2745763 | AJ19: 2 | AK19: 2 | AL19: =VLOOKUP($AL$6, 'Other Lists'!$B$27:$H$32, 7, FALSE) * AJ19 * 8 -> 648 | AM19: =VLOOKUP($AM$6, 'Other Lists'!$B$27:$H$32, 7, FALSE) * AK19 * 8 -> 648 | AN19: =SUM(AH19,AL19,AM19) -> 2937.6
... B70: 246 | C70: 45351 | D70: =WEEKDAY(C70, 1) -> 5 | E70: =_xlfn.ISOWEEKNUM(C70) -> 9 | F70: 3 | G70: 105 | H70: 134 | I70: 134 | J70: 44 | K70: 162 | L70: 7 | M70: 51 | N70: 172 | O70: =H70-I70 -> 0 | P70: =N70/I70 -> 1.2835821 | Q70: =VLOOKUP($G$8, 'Other Lists'!$B$13:$H$15, 7, FALSE) -> 184 | R70: =VLOOKUP($G$8, 'Other Lists'!$B$13:$F$15, 5, FALSE) -> 129 | S70: =VLOOKUP($G$8, 'Other Lists'!$B$13:$G$15, 6, FALSE) -> 36 | T70: =R70+S70 -> 165 | U70: =VLOOKUP($G$8, 'Other Lists'!$B$13:$H$15, 7, FALSE) *N70 -> 31648 | V70: =T70*I70 -> 22110 | W70: =U70-V70 -> 9538 | X70: =(I70-N70)*Q70 -> -6992 | Y70: =L70*W70 -> 66766 | Z70: 6 | AA70: 6 | AB70: 0 | AC70: 3 | AD70: =AA70-AB70-AC70-AJ70 -> 1 | AE70: =VLOOKUP($AE$6, 'Other Lists'!$B$27:$H$32, 7, FALSE) *AB70*8 -> 0 | AF70: =VLOOKUP($AF$6, 'Other Lists'!$B$27:$H$32, 7, FALSE) * AC70 * 8 -> 842.4 | AG70: =VLOOKUP($AG$6, 'Other Lists'!$B$27:$H$32, 7, FALSE) * AD70 * 8 -> 259.2 | AH70: =SUM($AE$8:$AG$8) -> 1641.6 | AI70: =AH70/I70 -> 12.250746 | AJ70: 2 | AK70: 1 | AL70: =VLOOKUP($AL$6, 'Other Lists'!$B$27:$H$32, 7, FALSE) * AJ70 * 8 -> 648 | AM70: =VLOOKUP($AM$6, 'Other Lists'!$B$27:$H$32, 7, FALSE) * AK70 * 8 -> 324 | AN70: =SUM(AH70,AL70,AM70) -> 2613.6

Sheet Line B - Shift 3
A1: Line B - Shift 3 Dataset Filtered - This dataset was filtered for creating Level 4 pivot table and visualization.
A2: Column for Week number was added (E)
A3: Column for Not Inspected Profit $ was added (Y)
G6: Line B Inspection Data | AE6: 1 | AF6: 4 | AG6: 3 | AL6: 5 | AM6: 6
B7: InspectDataID | C7: Date | D7: Day of Week | E7: Week | F7: Shift | G7: LineB-ProdType | H7: Received | I7: Received Inspected | J7: Leftover Inspected | K7: Capacity | L7: Not Inspected | M7: Left From Day Shift for 3rd Shift | N7: Inspect Pass | O7: Over/Under | P7: Pass% | Q7: Supplier Income per Part | R7: Supplier Cost to Make | S7: Supplier Other Cost | T7: Supplier Cost per Part | U7: Possible Supplier Income | V7: Supplier Cost of Parts | W7: Possible Supplier Profit | X7: Supplier Cost of Bad Parts | Y7: Not Inspected Profit $ | Z7: Inspectors | AA7: Inspectors | AB7: Training | AC7: Regular | AD7: Casual | AE7: Training $ | AF7: Regular $ | AG7: Casual $ | AH7: Total Line B $ | AI7: Inspect Labour $ per Part | AJ7: Team Lead | AK7: Shipper/Receiver/Porter | AL7: Team Lead $ | AM7: =AK7& " $" -> Shipper/Receiver/Porter $ | AN7: All Total Labour $
B8: 218 | C8: 45323 | D8: =WEEKDAY(C8, 1) -> 5 | E8: =_xlfn.ISOWEEKNUM(C8) -> 5 | F8: 3 | G8: 105 | H8: 165 | I8: 155 | J8: 0 | K8: 162 | L8: 0 | M8: 0 | N8: 148 | O8: =H8-I8 -> 10 | P8: =N8/I8 -> 0.95483871 | Q8: =VLOOKUP($G$8, 'Other Lists'!$B$13:$H$15, 7, FALSE) -> 184 | R8: =VLOOKUP($G$8, 'Other Lists'!$B$13:$F$15, 5, FALSE) -> 129 | S8: =VLOOKUP($G$8, 'Other Lists'!$B$13:$G$15, 6, FALSE) -> 36 | T8: =R8+S8 -> 165 | U8: =VLOOKUP($G$8, 'Other Lists'!$B$13:$H$15, 7, FALSE) *N8 -> 27232 | V8: =T8*I8 -> 25575 | W8: =U8-V8 -> 1657 | X8: =(I8-N8)*Q8 -> 1288 | Y8: =L8*W8 -> 0 | Z8: 6 | AA8: 6 | AB8: 0 | AC8: 4 | AD8: =AA8-AB8-AC8-AJ8 -> 0 | AE8: =VLOOKUP($AE$6, 'Other Lists'!$B$27:$H$32, 7, FALSE) *AB8*8 -> 0 | AF8: =VLOOKUP($AF$6, 'Other Lists'!$B$27:$H$32, 7, FALSE) * AC8 * 8 -> 1123.2 | AG8: =VLOOKUP($AG$6, 'Other Lists'!$B$27:$H$32, 7, FALSE) * AD8 * 8 -> 0 | AH8: =SUM(#REF!) -> #REF! | AI8: =AH8/I8 -> #REF! | AJ8: 2 | AK8: 1 | AL8: =VLOOKUP($AL$6, 'Other Lists'!$B$27:$H$32, 7, FALSE) * AJ8 * 8 -> 648 | AM8: =VLOOKUP($AM$6, 'Other Lists'!$B$27:$H$32, 7, FALSE) * AK8 * 8 -> 324 | AN8: =SUM(AH8,AL8,AM8) -> #REF!
B9: 219 | C9: 45324 | D9: =WEEKDAY(C9, 1) -> 6 | E9: =_xlfn.ISOWEEKNUM(C9) -> 5 | F9: 3 | G9: 105 | H9: 163 | I9: 163 | J9: 15 | K9: 162 | L9: 10 | M9: 25 | N9: 174 | O9: =H9-I9 -> 0 | P9: =N9/I9 -> 1.0674847 | Q9: =VLOOKUP($G$8, 'Other Lists'!$B$13:$H$15, 7, FALSE) -> 184 | R9: =VLOOKUP($G$8, 'Other Lists'!$B$13:$F$15, 5, FALSE) -> 129 | S9: =VLOOKUP($G$8, 'Other Lists'!$B$13:$G$15, 6, FALSE) -> 36 | T9: =R9+S9 -> 165 | U9: =VLOOKUP($G$8, 'Other Lists'!$B$13:$H$15, 7, FALSE) *N9 -> 32016 | V9: =T9*I9 -> 26895 | W9: =U9-V9 -> 5121 | X9: =(I9-N9)*Q9 -> -2024 | Y9: =L9*W9 -> 51210 | Z9: 6 | AA9: 6 | AB9: 0 | AC9: 4 | AD9: =AA9-AB9-AC9-AJ9 -> 0 | AE9: =VLOOKUP($AE$6, 'Other Lists'!$B$27:$H$32, 7, FALSE) *AB9*8 -> 0 | AF9: =VLOOKUP($AF$6, 'Other Lists'!$B$27:$H$32, 7, FALSE) * AC9 * 8 -> 1123.2 | AG9: =VLOOKUP($AG$6, 'Other Lists'!$B$27:$H$32, 7, FALSE) * AD9 * 8 -> 0 | AH9: =SUM(#REF!) -> #REF! | AI9: =AH9/I9 -> #REF! | AJ9: 2 | AK9: 1 | AL9: =VLOOKUP($AL$6, 'Other Lists'!$B$27:$H$32, 7, FALSE) * AJ9 * 8 -> 648 | AM9: =VLOOKUP($AM$6, 'Other Lists'!$B$27:$H$32, 7, FALSE) * AK9 * 8 -> 324 | AN9: =SUM(AH9,AL9,AM9) -> #REF!
B10: 220 | C10: 45325 | D10: =WEEKDAY(C10, 1) -> 7 | E10: =_xlfn.ISOWEEKNUM(C10) -> 5 | F10: 3 | G10: 105 | H10: 194 | I10: 157 | J10: 21 | K10: 162 | L10: 20 | M10: 41 | N10: 174 | O10: =H10-I10 -> 37 | P10: =N10/I10 -> 1.1082803 | Q10: =VLOOKUP($G$8, 'Other Lists'!$B$13:$H$15, 7, FALSE) -> 184 | R10: =VLOOKUP($G$8, 'Other Lists'!$B$13:$F$15, 5, FALSE) -> 129 | S10: =VLOOKUP($G$8, 'Other Lists'!$B$13:$G$15, 6, FALSE) -> 36 | T10: =R10+S10 -> 165 | U10: =VLOOKUP($G$8, 'Other Lists'!$B$13:$H$15, 7, FALSE) *N10 -> 32016 | V10: =T10*I10 -> 25905 | W10: =U10-V10 -> 6111 | X10: =(I10-N10)*Q10 -> -3128 | Y10: =L10*W10 -> 122220 | Z10: 6 | AA10: 6 | AB10: 0 | AC10: 4 | AD10: =AA10-AB10-AC10-AJ10 -> 0 | AE10: =VLOOKUP($AE$6, 'Other Lists'!$B$27:$H$32, 7, FALSE) *AB10*8 -> 0 | AF10: =VLOOKUP($AF$6, 'Other Lists'!$B$27:$H$32, 7, FALSE) * AC10 * 8 -> 1123.2 | AG10: =VLOOKUP($AG$6, 'Other Lists'!$B$27:$H$32, 7, FALSE) * AD10 * 8 -> 0 | AH10: =SUM(#REF!) -> #REF! | AI10: =AH10/I10 -> #REF! | AJ10: 2 | AK10: 1 | AL10: =VLOOKUP($AL$6, 'Other Lists'!$B$27:$H$32, 7, FALSE) * AJ10 * 8 -> 648 | AM10: =VLOOKUP($AM$6, 'Other Lists'!$B$27:$H$32, 7, FALSE) * AK10 * 8 -> 324 | AN10: =SUM(AH10,AL10,AM10) -> #REF!
B11: 223 | C11: 45328 | D11: =WEEKDAY(C11, 1) -> 3 | E11: =_xlfn.ISOWEEKNUM(C11) -> 6 | F11: 3 | G11: 105 | H11: 152 | I11: 152 | J11: 0 | K11: 162 | L11: 0 | M11: 0 | N11: 148 | O11: =H11-I11 -> 0 | P11: =N11/I11 -> 0.97368421 | Q11: =VLOOKUP($G$8, 'Other Lists'!$B$13:$H$15, 7, FALSE) -> 184 | R11: =VLOOKUP($G$8, 'Other Lists'!$B$13:$F$15, 5, FALSE) -> 129 | S11: =VLOOKUP($G$8, 'Other Lists'!$B$13:$G$15, 6, FALSE) -> 36 | T11: =R11+S11 -> 165 | U11: =VLOOKUP($G$8, 'Other Lists'!$B$13:$H$15, 7, FALSE) *N11 -> 27232 | V11: =T11*I11 -> 25080 | W11: =U11-V11 -> 2152 | X11: =(I11-N11)*Q11 -> 736 | Y11: =L11*W11 -> 0 | Z11: 6 | AA11: 6 | AB11: 0 | AC11: 3 | AD11: =AA11-AB11-AC11-AJ11 -> 1 | AE11: =VLOOKUP($AE$6, 'Other Lists'!$B$27:$H$32, 7, FALSE) *AB11*8 -> 0 | AF11: =VLOOKUP($AF$6, 'Other Lists'!$B$27:$H$32, 7, FALSE) * AC11 * 8 -> 842.4 | AG11: =VLOOKUP($AG$6, 'Other Lists'!$B$27:$H$32, 7, FALSE) * AD11 * 8 -> 259.2 | AH11: =SUM(#REF!) -> #REF! | AI11: =AH11/I11 -> #REF! | AJ11: 2 | AK11: 1 | AL11: =VLOOKUP($AL$6, 'Other Lists'!$B$27:$H$32, 7, FALSE) * AJ11 * 8 -> 648 | AM11: =VLOOKUP($AM$6, 'Other Lists'!$B$27:$H$32, 7, FALSE) * AK11 * 8 -> 324 | AN11: =SUM(AH11,AL11,AM11) -> #REF!
B12: 224 | C12: 45329 | D12: =WEEKDAY(C12, 1) -> 4 | E12: =_xlfn.ISOWEEKNUM(C12) -> 6 | F12: 3 | G12: 105 | H12: 173 | I12: 160 | J12: 18 | K12: 162 | L12: 53 | M12: 71 | N12: 174 | O12: =H12-I12 -> 13 | P12: =N12/I12 -> 1.0875 | Q12: =VLOOKUP($G$8, 'Other Lists'!$B$13:$H$15, 7, FALSE) -> 184 | R12: =VLOOKUP($G$8, 'Other Lists'!$B$13:$F$15, 5, FALSE) -> 129 | S12: =VLOOKUP($G$8, 'Other Lists'!$B$13:$G$15, 6, FALSE) -> 36 | T12: =R12+S12 -> 165 | U12: =VLOOKUP($G$8, 'Other Lists'!$B$13:$H$15, 7, FALSE) *N12 -> 32016 | V12: =T12*I12 -> 26400 | W12: =U12-V12 -> 5616 | X12: =(I12-N12)*Q12 -> -2576 | Y12: =L12*W12 -> 297648 | Z12: 6 | AA12: 6 | AB12: 0 | AC12: 4 | AD12: =AA12-AB12-AC12-AJ12 -> 0 | AE12: =VLOOKUP($AE$6, 'Other Lists'!$B$27:$H$32, 7, FALSE) *AB12*8 -> 0 | AF12: =VLOOKUP($AF$6, 'Other Lists'!$B$27:$H$32, 7, FALSE) * AC12 * 8 -> 1123.2 | AG12: =VLOOKUP($AG$6, 'Other Lists'!$B$27:$H$32, 7, FALSE) * AD12 * 8 -> 0 | AH12: =SUM(#REF!) -> #REF! | AI12: =AH12/I12 -> #REF! | AJ12: 2 | AK12: 1 | AL12: =VLOOKUP($AL$6, 'Other Lists'!$B$27:$H$32, 7, FALSE) * AJ12 * 8 -> 648 | AM12: =VLOOKUP($AM$6, 'Other Lists'!$B$27:$H$32, 7, FALSE) * AK12 * 8 -> 324 | AN12: =SUM(AH12,AL12,AM12) -> #REF!
B13: 225 | C13: 45330 | D13: =WEEKDAY(C13, 1) -> 5 | E13: =_xlfn.ISOWEEKNUM(C13) -> 6 | F13: 3 | G13: 105 | H13: 183 | I13: 158 | J13: 20 | K13: 162 | L13: 16 | M13: 36 | N13: 172 | O13: =H13-I13 -> 25 | P13: =N13/I13 -> 1.0886076 | Q13: =VLOOKUP($G$8, 'Other Lists'!$B$13:$H$15, 7, FALSE) -> 184 | R13: =VLOOKUP($G$8, 'Other Lists'!$B$13:$F$15, 5, FALSE) -> 129 | S13: =VLOOKUP($G$8, 'Other Lists'!$B$13:$G$15, 6, FALSE) -> 36 | T13: =R13+S13 -> 165 | U13: =VLOOKUP($G$8, 'Other Lists'!$B$13:$H$15, 7, FALSE) *N13 -> 31648 | V13: =T13*I13 -> 26070 | W13: =U13-V13 -> 5578 | X13: =(I13-N13)*Q13 -> -2576 | Y13: =L13*W13 -> 89248 | Z13: 6 | AA13: 6 | AB13: 0 | AC13: 4 | AD13: =AA13-AB13-AC13-AJ13 -> 0 | AE13: =VLOOKUP($AE$6, 'Other Lists'!$B$27:$H$32, 7, FALSE) *AB13*8 -> 0 | AF13: =VLOOKUP($AF$6, 'Other Lists'!$B$27:$H$32, 7, FALSE) * AC13 * 8 -> 1123.2 | AG13: =VLOOKUP($AG$6, 'Other Lists'!$B$27:$H$32, 7, FALSE) * AD13 * 8 -> 0 | AH13: =SUM(#REF!) -> #REF! | AI13: =AH13/I13 -> #REF! | AJ13: 2 | AK13: 1 | AL13: =VLOOKUP($AL$6, 'Other Lists'!$B$27:$H$32, 7, FALSE) * AJ13 * 8 -> 648 | AM13: =VLOOKUP($AM$6, 'Other Lists'!$B$27:$H$32, 7, FALSE) * AK13 * 8 -> 324 | AN13: =SUM(AH13,AL13,AM13) -> #REF!
B14: 226 | C14: 45331 | D14: =WEEKDAY(C14, 1) -> 6 | E14: =_xlfn.ISOWEEKNUM(C14) -> 6 | F14: 3 | G14: 105 | H14: 176 | I14: 153 | J14: 25 | K14: 162 | L14: 8 | M14: 33 | N14: 174 | O14: =H14-I14 -> 23 | P14: =N14/I14 -> 1.1372549 | Q14: =VLOOKUP($G$8, 'Other Lists'!$B$13:$H$15, 7, FALSE) -> 184 | R14: =VLOOKUP($G$8, 'Other Lists'!$B$13:$F$15, 5, FALSE) -> 129 | S14: =VLOOKUP($G$8, 'Other Lists'!$B$13:$G$15, 6, FALSE) -> 36 | T14: =R14+S14 -> 165 | U14: =VLOOKUP($G$8, 'Other Lists'!$B$13:$H$15, 7, FALSE) *N14 -> 32016 | V14: =T14*I14 -> 25245 | W14: =U14-V14 -> 6771 | X14: =(I14-N14)*Q14 -> -3864 | Y14: =L14*W14 -> 54168 | Z14: 6 | AA14: 6 | AB14: 0 | AC14: 4 | AD14: =AA14-AB14-AC14-AJ14 -> 0 | AE14: =VLOOKUP($AE$6, 'Other Lists'!$B$27:$H$32, 7, FALSE) *AB14*8 -> 0 | AF14: =VLOOKUP($AF$6, 'Other Lists'!$B$27:$H$32, 7, FALSE) * AC14 * 8 -> 1123.2 | AG14: =VLOOKUP($AG$6, 'Other Lists'!$B$27:$H$32, 7, FALSE) * AD14 * 8 -> 0 | AH14: =SUM(#REF!) -> #REF! | AI14: =AH14/I14 -> #REF! | AJ14: 2 | AK14: 1 | AL14: =VLOOKUP($AL$6, 'Other Lists'!$B$27:$H$32, 7, FALSE) * AJ14 * 8 -> 648 | AM14: =VLOOKUP($AM$6, 'Other Lists'!$B$27:$H$32, 7, FALSE) * AK14 * 8 -> 324 | AN14: =SUM(AH14,AL14,AM14) -> #REF!
B15: 227 | C15: 45332 | D15: =WEEKDAY(C15, 1) -> 7 | E15: =_xlfn.ISOWEEKNUM(C15) -> 6 | F15: 3 | G15: 105 | H15: 171 | I15: 133 | J15: 24 | K15: 162 | L15: 0 | M15: 24 | N15: 147 | O15: =H15-I15 -> 38 | P15: =N15/I15 -> 1.1052632 | Q15: =VLOOKUP($G$8, 'Other Lists'!$B$13:$H$15, 7, FALSE) -> 184 | R15: =VLOOKUP($G$8, 'Other Lists'!$B$13:$F$15, 5, FALSE) -> 129 | S15: =VLOOKUP($G$8, 'Other Lists'!$B$13:$G$15, 6, FALSE) -> 36 | T15: =R15+S15 -> 165 | U15: =VLOOKUP($G$8, 'Other Lists'!$B$13:$H$15, 7, FALSE) *N15 -> 27048 | V15: =T15*I15 -> 21945 | W15: =U15-V15 -> 5103 | X15: =(I15-N15)*Q15 -> -2576 | Y15: =L15*W15 -> 0 | Z15: 6 | AA15: 5 | AB15: 0 | AC15: 3 | AD15: =AA15-AB15-AC15-AJ15 -> 0 | AE15: =VLOOKUP($AE$6, 'Other Lists'!$B$27:$H$32, 7, FALSE) *AB15*8 -> 0 | AF15: =VLOOKUP($AF$6, 'Other Lists'!$B$27:$H$32, 7, FALSE) * AC15 * 8 -> 842.4 | AG15: =VLOOKUP($AG$6, 'Other Lists'!$B$27:$H$32, 7, FALSE) * AD15 * 8 -> 0 | AH15: =SUM(#REF!) -> #REF! | AI15: =AH15/I15 -> #REF! | AJ15: 2 | AK15: 1 | AL15: =VLOOKUP($AL$6, 'Other Lists'!$B$27:$H$32, 7, FALSE) * AJ15 * 8 -> 648 | AM15: =VLOOKUP($AM$6, 'Other Lists'!$B$27:$H$32, 7, FALSE) * AK15 * 8 -> 324 | AN15: =SUM(AH15,AL15,AM15) -> #REF!
B16: 230 | C16: 45335 | D16: =WEEKDAY(C16, 1) -> 3 | E16: =_xlfn.ISOWEEKNUM(C16) -> 7 | F16: 3 | G16: 105 | H16: 153 | I16: 153 | J16: 2 | K16: 162 | L16: 0 | M16: 2 | N16: 151 | O16: =H16-I16 -> 0 | P16: =N16/I16 -> 0.9869281 | Q16: =VLOOKUP($G$8, 'Other Lists'!$B$13:$H$15, 7, FALSE) -> 184 | R16: =VLOOKUP($G$8, 'Other Lists'!$B$13:$F$15, 5, FALSE) -> 129 | S16: =VLOOKUP($G$8, 'Other Lists'!$B$13:$G$15, 6, FALSE) -> 36 | T16: =R16+S16 -> 165 | U16: =VLOOKUP($G$8, 'Other Lists'!$B$13:$H$15, 7, FALSE) *N16 -> 27784 | V16: =T16*I16 -> 25245 | W16: =U16-V16 -> 2539 | X16: =(I16-N16)*Q16 -> 368 | Y16: =L16*W16 -> 0 | Z16: 6 | AA16: 6 | AB16: 0 | AC16: 3 | AD16: =AA16-AB16-AC16-AJ16 -> 1 | AE16: =VLOOKUP($AE$6, 'Other Lists'!$B$27:$H$32, 7, FALSE) *AB16*8 -> 0 | AF16: =VLOOKUP($AF$6, 'Other Lists'!$B$27:$H$32, 7, FALSE) * AC16 * 8 -> 842.4 | AG16: =VLOOKUP($AG$6, 'Other Lists'!$B$27:$H$32, 7, FALSE) * AD16 * 8 -> 259.2 | AH16: =SUM(#REF!) -> #REF! | AI16: =AH16/I16 -> #REF! | AJ16: 2 | AK16: 1 | AL16: =VLOOKUP($AL$6, 'Other Lists'!$B$27:$H$32, 7, FALSE) * AJ16 * 8 -> 648 | AM16: =VLOOKUP($AM$6, 'Other Lists'!$B$27:$H$32, 7, FALSE) * AK16 * 8 -> 324 | AN16: =SUM(AH16,AL16,AM16) -> #REF!
B17: 231 | C17: 45336 | D17: =WEEKDAY(C17, 1) -> 4 | E17: =_xlfn.ISOWEEKNUM(C17) -> 7 | F17: 3 | G17: 105 | H17: 153 | I17: 153 | J17: 25 | K17: 162 | L17: 4 | M17: 29 | N17: 165 | O17: =H17-I17 -> 0 | P17: =N17/I17 -> 1.0784314 | Q17: =VLOOKUP($G$8, 'Other Lists'!$B$13:$H$15, 7, FALSE) -> 184 | R17: =VLOOKUP($G$8, 'Other Lists'!$B$13:$F$15, 5, FALSE) -> 129 | S17: =VLOOKUP($G$8, 'Other Lists'!$B$13:$G$15, 6, FALSE) -> 36 | T17: =R17+S17 -> 165 | U17: =VLOOKUP($G$8, 'Other Lists'!$B$13:$H$15, 7, FALSE) *N17 -> 30360 | V17: =T17*I17 -> 25245 | W17: =U17-V17 -> 5115 | X17: =(I17-N17)*Q17 -> -2208 | Y17: =L17*W17 -> 20460 | Z17: 6 | AA17: 6 | AB17: 0 | AC17: 3 | AD17: =AA17-AB17-AC17-AJ17 -> 1 | AE17: =VLOOKUP($AE$6, 'Other Lists'!$B$27:$H$32, 7, FALSE) *AB17*8 -> 0 | AF17: =VLOOKUP($AF$6, 'Other Lists'!$B$27:$H$32, 7, FALSE) * AC17 * 8 -> 842.4 | AG17: =VLOOKUP($AG$6, 'Other Lists'!$B$27:$H$32, 7, FALSE) * AD17 * 8 -> 259.2 | AH17: =SUM(#REF!) -> #REF! | AI17: =AH17/I17 -> #REF! | AJ17: 2 | AK17: 1 | AL17: =VLOOKUP($AL$6, 'Other Lists'!$B$27:$H$32, 7, FALSE) * AJ17 * 8 -> 648 | AM17: =VLOOKUP($AM$6, 'Other Lists'!$B$27:$H$32, 7, FALSE) * AK17 * 8 -> 324 | AN17: =SUM(AH17,AL17,AM17) -> #REF!
B18: 232 | C18: 45337 | D18: =WEEKDAY(C18, 1) -> 5 | E18: =_xlfn.ISOWEEKNUM(C18) -> 7 | F18: 3 | G18: 105 | H18: 162 | I18: 155 | J18: 0 | K18: 162 | L18: 0 | M18: 0 | N18: 150 | O18: =H18-I18 -> 7 | P18: =N18/I18 -> 0.96774194 | Q18: =VLOOKUP($G$8, 'Other Lists'!$B$13:$H$15, 7, FALSE) -> 184 | R18: =VLOOKUP($G$8, 'Other Lists'!$B$13:$F$15, 5, FALSE) -> 129 | S18: =VLOOKUP($G$8, 'Other Lists'!$B$13:$G$15, 6, FALSE) -> 36 | T18: =R18+S18 -> 165 | U18: =VLOOKUP($G$8, 'Other Lists'!$B$13:$H$15, 7, FALSE) *N18 -> 27600 | V18: =T18*I18 -> 25575 | W18: =U18-V18 -> 2025 | X18: =(I18-N18)*Q18 -> 920 | Y18: =L18*W18 -> 0 | Z18: 6 | AA18: 6 | AB18: 0 | AC18: 4 | AD18: =AA18-AB18-AC18-AJ18 -> 0 | AE18: =VLOOKUP($AE$6, 'Other Lists'!$B$27:$H$32, 7, FALSE) *AB18*8 -> 0 | AF18: =VLOOKUP($AF$6, 'Other Lists'!$B$27:$H$32, 7, FALSE) * AC18 * 8 -> 1123.2 | AG18: =VLOOKUP($AG$6, 'Other Lists'!$B$27:$H$32, 7, FALSE) * AD18 * 8 -> 0 | AH18: =SUM(#REF!) -> #REF! | AI18: =AH18/I18 -> #REF! | AJ18: 2 | AK18: 1 | AL18: =VLOOKUP($AL$6, 'Other Lists'!$B$27:$H$32, 7, FALSE) * AJ18 * 8 -> 648 | AM18: =VLOOKUP($AM$6, 'Other Lists'!$B$27:$H$32, 7, FALSE) * AK18 * 8 -> 324 | AN18: =SUM(AH18,AL18,AM18) -> #REF!
B19: 233 | C19: 45338 | D19: =WEEKDAY(C19, 1) -> 6 | E19: =_xlfn.ISOWEEKNUM(C19) -> 7 | F19: 3 | G19: 105 | H19: 189 | I19: 158 | J19: 0 | K19: 162 | L19: 0 | M19: 0 | N19: 151 | O19: =H19-I19 -> 31 | P19: =N19/I19 -> 0.9556962 | Q19: =VLOOKUP($G$8, 'Other Lists'!$B$13:$H$15, 7, FALSE) -> 184 | R19: =VLOOKUP($G$8, 'Other Lists'!$B$13:$F$15, 5, FALSE) -> 129 | S19: =VLOOKUP($G$8, 'Other Lists'!$B$13:$G$15, 6, FALSE) -> 36 | T19: =R19+S19 -> 165 | U19: =VLOOKUP($G$8, 'Other Lists'!$B$13:$H$15, 7, FALSE) *N19 -> 27784 | V19: =T19*I19 -> 26070 | W19: =U19-V19 -> 1714 | X19: =(I19-N19)*Q19 -> 1288 | Y19: =L19*W19 -> 0 | Z19: 6 | AA19: 6 | AB19: 0 | AC19: 3 | AD19: =AA19-AB19-AC19-AJ19 -> 1 | AE19: =VLOOKUP($AE$6, 'Other Lists'!$B$27:$H$32, 7, FALSE) *AB19*8 -> 0 | AF19: =VLOOKUP($AF$6, 'Other Lists'!$B$27:$H$32, 7, FALSE) * AC19 * 8 -> 842.4 | AG19: =VLOOKUP($AG$6, 'Other Lists'!$B$27:$H$32, 7, FALSE) * AD19 * 8 -> 259.2 | AH19: =SUM(#REF!) -> #REF! | AI19: =AH19/I19 -> #REF! | AJ19: 2 | AK19: 1 | AL19: =VLOOKUP($AL$6, 'Other Lists'!$B$27:$H$32, 7, FALSE) * AJ19 * 8 -> 648 | AM19: =VLOOKUP($AM$6, 'Other Lists'!$B$27:$H$32, 7, FALSE) * AK19 * 8 -> 324 | AN19: =SUM(AH19,AL19,AM19) -> #REF!
... B28: 246 | C28: 45351 | D28: =WEEKDAY(C28, 1) -> 5 | E28: =_xlfn.ISOWEEKNUM(C28) -> 9 | F28: 3 | G28: 105 | H28: 134 | I28: 134 | J28: 44 | K28: 162 | L28: 7 | M28: 51 | N28: 172 | O28: =H28-I28 -> 0 | P28: =N28/I28 -> 1.2835821 | Q28: =VLOOKUP($G$8, 'Other Lists'!$B$13:$H$15, 7, FALSE) -> 184 | R28: =VLOOKUP($G$8, 'Other Lists'!$B$13:$F$15, 5, FALSE) -> 129 | S28: =VLOOKUP($G$8, 'Other Lists'!$B$13:$G$15, 6, FALSE) -> 36 | T28: =R28+S28 -> 165 | U28: =VLOOKUP($G$8, 'Other Lists'!$B$13:$H$15, 7, FALSE) *N28 -> 31648 | V28: =T28*I28 -> 22110 | W28: =U28-V28 -> 9538 | X28: =(I28-N28)*Q28 -> -6992 | Y28: =L28*W28 -> 66766 | Z28: 6 | AA28: 6 | AB28: 0 | AC28: 3 | AD28: =AA28-AB28-AC28-AJ28 -> 1 | AE28: =VLOOKUP($AE$6, 'Other Lists'!$B$27:$H$32, 7, FALSE) *AB28*8 -> 0 | AF28: =VLOOKUP($AF$6, 'Other Lists'!$B$27:$H$32, 7, FALSE) * AC28 * 8 -> 842.4 | AG28: =VLOOKUP($AG$6, 'Other Lists'!$B$27:$H$32, 7, FALSE) * AD28 * 8 -> 259.2 | AH28: =SUM(#REF!) -> #REF! | AI28: =AH28/I28 -> #REF! | AJ28: 2 | AK28: 1 | AL28: =VLOOKUP($AL$6, 'Other Lists'!$B$27:$H$32, 7, FALSE) * AJ28 * 8 -> 648 | AM28: =VLOOKUP($AM$6, 'Other Lists'!$B$27:$H$32, 7, FALSE) * AK28 * 8 -> 324 | AN28: =SUM(AH28,AL28,AM28) -> #REF!

Sheet Level 0
A1: Level 0 - Weekly Stranded Parts
A4: Sum of Not Inspected Profit $ | C4: Shift
A5: Week | B5: LineB-ProdType | C5: 1 | D5: 2 | E5: 3
A6: 5 | B6: 105 | C6: 111006 | D6: 17578 | E6: 173430
A7: 6 | B7: 105 | C7: 140853 | D7: 113541 | E7: 441064
A8: 7 | B8: 105 | C8: 71553 | D8: 53534 | E8: 56760
A9: 8 | B9: 105 | C9: 157207 | D9: 78198 | E9: 110496
A10: 9 | B10: 105 | C10: 5366 | D10: 132039 | E10: 66766
A11: Grand Total | C11: 485985 | D11: 394890 | E11: 848516
A25: Question | B25: Why are Product Types' Profits on Parts not maximum?
A26: Chosen Answer | B26: 1. Parts that are not inspected during the first day never get inspected.
A27: Why | B27: To investigate this, I used the metric: Weekly uninspected profit $ by product type. This metric reveals how much supplier profit is lost each week due to parts not being inspected on time.
A28: Insights | B28: Relevance to LPQI: This chart reveals how late or missed inspections lead to significant profit loss, especially in Shift 3. LPQI can use this to track backlog cost by shift and week. Use for LPQI: This can guide LPQI to assign more trained inspectors to Shift 3 or reconfigure part queues so early-day backlogs don’t accumulate, protecting high-margin inventory.

Sheet Level 1
A1: Level 1 - Reverse Level 0
A3: Sum of Not Inspected | C3: Shift
A4: Week | B4: LineB-ProdType | C4: 1 | D4: 2 | E4: 3
A5: 5 | B5: 105 | C5: 49 | D5: 17 | E5: 30
A6: 6 | B6: 105 | C6: 72 | D6: 92 | E6: 77
A7: 7 | B7: 105 | C7: 45 | D7: 29 | E7: 9
A8: 8 | B8: 105 | C8: 77 | D8: 40 | E8: 12
A9: 9 | B9: 105 | C9: 2 | D9: 51 | E9: 7
A10: Grand Total | C10: 245 | D10: 229 | E10: 135
A19: Question | B19: Why are the counts of stranded parts high each week?
A20: Chosen Answer | B20: 1. High-profit parts are missed due to inefficient prioritization.
A21: Why | B21: To investigate this, I used the metric: Weekly count of uninspected parts by product type. This metric reverses the profit view and focuses instead on volume — how many parts, not just how much profit, are missed weekly.
A22: Insights | B22: Relevance to LPQI: This chart highlights how inspection delays on certain days—especially during Shift 3—translate into high daily profit losses. LPQI can use this to pinpoint when scheduling inefficiencies create costly backlog spikes. Use for LPQI: This can help LPQI proactively adjust daily scheduling by forecasting demand peaks and assigning inspection resources accordingly, especially on high-risk days like Feb 7 and Feb 20, to minimize stranded profit.

Sheet Level 2
A1: Level 2 - Daily Stranded Parts
A3: Sum of Not Inspected Profit $ | C3: Shift
A4: Date | B4: LineB-ProdType | C4: 1 | D4: 2 | E4: 3 | F4: Grand Total
A5: 45323 | B5: 105 | C5: 0 | D5: 0 | E5: 0 | F5: 0
A6: 45324 | B6: 105 | C6: 9080 | D6: 17578 | E6: 51210 | F6: 77868
A7: 45325 | B7: 105 | C7: 101926 | D7: 0 | E7: 122220 | F7: 224146
A8: 45328 | B8: 105 | C8: 0 | D8: 0 | E8: 0 | F8: 0
A9: 45329 | B9: 105 | C9: 30498 | D9: 63990 | E9: 297648 | F9: 392136
A10: 45330 | B10: 105 | C10: 47566 | D10: 19171 | E10: 89248 | F10: 155985
A11: 45331 | B11: 105 | C11: 11765 | D11: 30380 | E11: 54168 | F11: 96313
A12: 45332 | B12: 105 | C12: 51024 | D12: 0 | E12: 0 | F12: 51024
A13: 45335 | B13: 105 | C13: 5290 | D13: 0 | E13: 0 | F13: 5290
A14: 45336 | B14: 105 | C14: 0 | D14: 53534 | E14: 20460 | F14: 73994
A15: 45337 | B15: 105 | C15: 0 | D15: 0 | E15: 0 | F15: 0
A16: 45338 | B16: 105 | C16: 0 | D16: 0 | E16: 0 | F16: 0
... A25: 45351 | B25: 105 | C25: 0 | D25: 132039 | E25: 66766 | F25: 198805
A26: Grand Total | C26: 485985 | D26: 394890 | E26: 848516 | F26: 1729391
A32: Question | B32: Why is there a recurring backlog despite known workload?
A33: Chosen Answer | B33: 1. Poor scheduling doesn’t account for daily capacity limits.
A34: Why | B34: To investigate this, I used the metric: Daily uninspected profit $ by product type. This reveals how much profit is lost each day due to parts not being inspected, helping assess how well scheduling aligns with daily workload patterns.
A35: Insights | B35: Relevance to LPQI: This visualization reveals how poor scheduling results in profit loss spikes on certain days, particularly in Shift 3. LPQI can use this chart to monitor day-wise inspection gaps that trigger missed profit opportunities. Use for LPQI: LPQI can improve inspection efficiency by matching capacity with peak-day demand and rebalancing workloads across shifts—especially Shift 3—to reduce frequent stranded parts and recurring daily backlogs.

Sheet Level 3
A1: Level 3 - Reverse Level 2
A3: Sum of Not Inspected | C3: Shift
A4: Date | B4: LineB-ProdType | C4: 1 | D4: 2 | E4: 3 | F4: Grand Total
A5: 45323 | B5: 105 | C5: 0 | D5: 0 | E5: 0 | F5: 0
A6: 45324 | B6: 105 | C6: 8 | D6: 17 | E6: 10 | F6: 35
A7: 45325 | B7: 105 | C7: 41 | D7: 0 | E7: 20 | F7: 61
A8: 45328 | B8: 105 | C8: 0 | D8: 0 | E8: 0 | F8: 0
A9: 45329 | B9: 105 | C9: 26 | D9: 45 | E9: 53 | F9: 124
A10: 45330 | B10: 105 | C10: 17 | D10: 19 | E10: 16 | F10: 52
A11: 45331 | B11: 105 | C11: 5 | D11: 28 | E11: 8 | F11: 41
A12: 45332 | B12: 105 | C12: 24 | D12: 0 | E12: 0 | F12: 24
A13: 45335 | B13: 105 | C13: 2 | D13: 0 | E13: 0 | F13: 2
A14: 45336 | B14: 105 | C14: 0 | D14: 29 | E14: 4 | F14: 33
A15: 45337 | B15: 105 | C15: 0 | D15: 0 | E15: 0 | F15: 0
A16: 45338 | B16: 105 | C16: 0 | D16: 0 | E16: 0 | F16: 0
... A25: 45351 | B25: 105 | C25: 0 | D25: 51 | E25: 7 | F25: 58
A26: Grand Total | C26: 245 | D26: 229 | E26: 135 | F26: 609
A28: Question | B28: Why are certain parts missed more often across weekdays?
A29: Chosen Answer | B29: 1. Inconsistent delivery scheduling of TBI parts.
A30: Why | B30: To explore this question, I used the metric: Daily count of uninspected parts by product type. This reverse view of Level 2 emphasizes when parts are missed in terms of weekday patterns and across shifts, shedding light on delivery or staging inconsistencies.
A31: Insights | B31: Relevance to LPQI: This visualization uncovers irregular patterns in uninspected parts across shifts and weekdays, suggesting breakdowns in consistent part delivery. LPQI can use this to detect risks of unsynchronized inflow and weekday-based backlogs. Use for LPQI: LPQI can coordinate TBI delivery scheduling and balance shift-wise inflow to avoid spikes. Ensuring steady, predictable part supply across weekdays can improve inspection throughput and prevent inspection failures.

Sheet Level 4
A1: Level 4 - Capacity
A3: Date | B3: LineB-ProdType | C3: Sum of Capacity | D3: Sum of Received | E3: Sum of Received Inspected | F3: Sum of Not Inspected
A4: 45323 | B4: 105 | C4: 162 | D4: 165 | E4: 155 | F4: 0
A5: 45324 | B5: 105 | C5: 162 | D5: 163 | E5: 163 | F5: 10
A6: 45325 | B6: 105 | C6: 162 | D6: 194 | E6: 157 | F6: 20
A7: 45328 | B7: 105 | C7: 162 | D7: 152 | E7: 152 | F7: 0
A8: 45329 | B8: 105 | C8: 162 | D8: 173 | E8: 160 | F8: 53
A9: 45330 | B9: 105 | C9: 162 | D9: 183 | E9: 158 | F9: 16
A10: 45331 | B10: 105 | C10: 162 | D10: 176 | E10: 153 | F10: 8
A11: 45332 | B11: 105 | C11: 162 | D11: 171 | E11: 133 | F11: 0
A12: 45335 | B12: 105 | C12: 162 | D12: 153 | E12: 153 | F12: 0
A13: 45336 | B13: 105 | C13: 162 | D13: 153 | E13: 153 | F13: 4
A14: 45337 | B14: 105 | C14: 162 | D14: 162 | E14: 155 | F14: 0
A15: 45338 | B15: 105 | C15: 162 | D15: 189 | E15: 158 | F15: 0
... A24: 45351 | B24: 105 | C24: 162 | D24: 134 | E24: 134 | F24: 7
A25: Grand Total | C25: 3402 | D25: 3368 | E25: 3140 | F25: 135
A27: Question | B27: Why is the inspection line not adapting to capacity limits efficiently?
A28: Chosen Answer | B28: 1. No priority queue system for high-profit parts.
A29: Why | B29: To explore this, I used the metric: Day vs Capacity vs Received vs Received Inspected vs Stranded Parts. This metric captures how well daily inspection capacity is utilized in comparison to the number of parts received and ultimately left uninspected. A mismatch here highlights inefficiencies in how parts are queued, prioritized, and cleared for inspection.
A30: Insights | B30: Relevance to LPQI: This visualization highlights a mismatch between received volume and inspection throughput, confirming that fixed capacity without prioritization leads to stranded parts. LPQI can use this to diagnose queueing inefficiencies. Use for LPQI: LPQI should implement a dynamic priority system that allocates inspection resources based on part value and urgency. This would prevent high-margin items from being overlooked during volume spikes and reduce long-term backlog.

Sheet Other Lists
A1: Little Panda Quality Inspection - Reference Tables | G1: =ReadMeFirst!D1&" "&ReadMeFirst!E1 -> Data Set B
B5: Suppliers of Parts to Be Inspected
B6: MakerID | C6: Maker | D6: Plant Location
B7: 55 | C7: Eclipse | D7: Cambridge, ON
B8: 92 | C8: Linacar | D8: Guelph, ON
Q9: Suppliers of Parts TBI - Production Lines / Cells Codes
Q10: =R13&"-"&S13
B11: Factors on Parts to be Inspected | K11: =INT(7/(I13*J13/60))
B12: ProdTypeID | C12: Product Type | D12: MakerID | E12: Prodn Lines / Cells | F12: Cost To Make | G12: Other Costs | H12: Sells For | I12: Inspect Tests | J12: Avg Mins Per Inspect | K12: Total Per 7 hrs per Inspector | L12: NightShift | M12: Porter Mins | N12: Box Qty | Q12: Key | R12: ProdTypeID | S12: Sequence | T12: MakerID | U12: Prodn Lines / Cells
B13: 105 | C13: Alternator | D13: 55 | E13: 3 | F13: 129 | G13: 36 | H13: 184 | I13: 14 | J13: 1.1 | K13: =INT(7/(I13*J13/60)) -> 27 | L13: =ROUNDUP(K13/2,0) -> 14 | M13: 0.35 | N13: 12 | Q13: =R13&"-"&S13 -> 105-1 | R13: 105 | S13: 1 | T13: 55 | U13: G
B14: 119 | C14: Tie Rod End | D14: 92 | E14: 6 | F14: 17.8 | G14: 11 | H14: 32 | I14: 6 | J14: 0.4 | K14: =7/(I14*J14/60) -> 175 | L14: =ROUNDUP(K14/2,0) -> 88 | M14: 0.2 | N14: 50 | Q14: =R14&"-"&S14 -> 105-2 | R14: 105 | S14: 2 | T14: 55 | U14: H
B15: 201 | C15: Ball Joint | D15: 92 | E15: 4 | F15: 32.6 | G15: 16.5 | H15: 71 | I15: 10 | J15: 0.6 | K15: =7/(I15*J15/60) -> 70 | L15: =ROUNDUP(K15/2,0) -> 35 | M15: 0.2 | N15: 40 | Q15: =R15&"-"&S15 -> 105-3 | R15: 105 | S15: 3 | T15: 55 | U15: J
Q16: =R16&"-"&S16 -> 119-1 | R16: 119 | S16: 1 | T16: 92 | U16: D1
Q17: =R17&"-"&S17 -> 119-2 | R17: 119 | S17: 2 | T17: 92 | U17: D2
B18: Employee Groups | Q18: =R18&"-"&S18 -> 119-3 | R18: 119 | S18: 3 | T18: 92 | U18: D3
B19: EmpGroupID | C19: EmployeeGroup | Q19: =R19&"-"&S19 -> 119-4 | R19: 119 | S19: 4 | T19: 92 | U19: D4
B20: 101 | C20: Inspector | Q20: =R20&"-"&S20 -> 119-5 | R20: 119 | S20: 5 | T20: 92 | U20: D5
B21: 102 | C21: Team Lead | Q21: =R21&"-"&S21 -> 119-6 | R21: 119 | S21: 6 | T21: 92 | U21: D6
B22: 103 | C22: Shipper/Receiver | Q22: =R22&"-"&S22 -> 201-1 | R22: 201 | S22: 1 | T22: 92 | U22: M5
Q23: =R23&"-"&S23 -> 201-2 | R23: 201 | S23: 2 | T23: 92 | U23: M6
Q24: =R24&"-"&S24 -> 201-3 | R24: 201 | S24: 3 | T24: 92 | U24: M7
B25: Employee Payrates | Q25: =R25&"-"&S25 -> 201-4 | R25: 201 | S25: 4 | T25: 92 | U25: M8
B26: EmpTypeID | C26: Employee Types | D26: Experience | E26: EmpGroupID | F26: Payrate / hr | G26: Employer Share | H26: Total Cost/Hr
B27: 1 | C27: Training | E27: 101 | F27: 18 | G27: =F27*0.35 -> 6.3 | H27: =F27+G27 -> 24.3
B28: 2 | C28: Casual | D28: Under 100 hours | E28: 101 | F28: 22 | G28: =F28*0.35 -> 7.7 | H28: =F28+G28 -> 29.7
B29: 3 | C29: Casual | D29: 101-300 hours | E29: 101 | F29: 24 | G29: =F29*0.35 -> 8.4 | H29: =F29+G29 -> 32.4
B30: 4 | C30: Regular | D30: 301+ hours | E30: 101 | F30: 26 | G30: =F30*0.35 -> 9.1 | H30: =F30+G30 -> 35.1
B31: 5 | C31: Team Lead | D31: 501+ hours | E31: 102 | F31: 30 | G31: =F31*0.35 -> 10.5 | H31: =F31+G31 -> 40.5
B32: 6 | C32: Shipper/Receiver | E32: 103 | F32: 30 | G32: =F32*0.35 -> 10.5 | H32: =F32+G32 -> 40.5
B35: Shift Factors
B36: ShiftID | C36: ShiftName | D36: ShiftHours | E36: Shift Premium
B37: 1 | C37: Day | D37: 6am-2pm | E37: 0
B38: 2 | C38: Afternoon | D38: 2pm-10pm | E38: 0.1
B39: 3 | C39: Nights | D39: 10pm-6am | E39: 0.35
B41: Inspection Lines
B42: InspectLineID | C42: InspectLine Name
B43: A | C43: Line A
B44: B | C44: Line B
G46: =D49&E49&"-"&H49&"-"&F49
B47: Inspection Line, Shift, WeekDay/WeekEnd Staffing Counts
...

Sheet Inspect DM
A1: Little Panda Inspection Lines A and B Inspection Data | G1: =ReadMeFirst!D1&" "&ReadMeFirst!E1 -> Data Set B
G2: Some cells were converted from #DIV/0! as workers did not work on Sunday and Monday shifts.
F6: Line A Inspection Data | AB6: 1 | AC6: 4 | AD6: 3 | AH6: Line B Inspection Data | BE6: 1 | BF6: 4 | BG6: 3 | BM6: 5 | BN6: 6
B7: InspectDataID | C7: Date | D7: Day of Week | E7: Shift | F7: LineA-ProdType | G7: Received | H7: Received Inspected | I7: Leftover Inspected | J7: Capacity | K7: Not Inspected | L7: Left From Day Shift for 3rd Shift | M7: Inspect Pass | N7: Over / Under | O7: Pass% | P7: Supplier Income per Part | Q7: Supplier Cost to Make | R7: Supplier Other Cost | S7: Supplier Cost per Part | T7: Possible Supplier Income | U7: Supplier Cost of Parts | V7: Possible Supplier Profit | W7: Supplier Cost of Bad Parts | X7: Inspectors | Y7: Training | Z7: Regular | AA7: Casual | AB7: Training $ | AC7: Regular $ | AD7: Casual $ | AE7: Total Line A $ | AF7: Inspect Labour $ per Part | AH7: LineB-ProdType | AI7: Received | AJ7: Received Inspected | AK7: Leftover Inspected | AL7: Capacity | AM7: Not Inspected | AN7: Left From Day Shift for 3rd Shift | AO7: Inspect Pass | AP7: Over/Under | AQ7: Pass% | AR7: Supplier Income per Part | AS7: Supplier Cost to Make | AT7: Supplier Other Cost | AU7: Supplier Cost per Part | AV7: Possible Supplier Income | AW7: Supplier Cost of Parts | AX7: Possible Supplier Profit | AY7: Supplier Cost of Bad Parts | AZ7: Inspectors | BA7: Inspectors | BB7: Training | BC7: Regular | BD7: Casual | BE7: Training $ | BF7: Regular $ | BG7: Casual $ | BH7: Total Line B $ | BI7: Inspect Labour $ per Part | BK7: Team Lead | BL7: Shipper/Receiver/Porter | BM7: Team Lead $ | BN7: =BL7& " $" -> Shipper/Receiver/Porter $ | BO7: All Total Labour $
B8: 160 | C8: 45323 | D8: =WEEKDAY(C8, 1) -> 5 | E8: 1 | F8: 119 | G8: 1260 | H8: 1050 | I8: 0 | J8: 1050 | K8: 210 | L8: 0 | M8: 997 | N8: =G8-H8 -> 210 | O8: =M8/H8 -> 0.94952381 | P8: =VLOOKUP(F8, 'Other Lists'!$B$13:$H$154, 7, FALSE) -> 32 | Q8: =VLOOKUP(F8, 'Other Lists'!$B$13:$F$15, 5, FALSE) -> 17.8 | R8: =VLOOKUP(F8, 'Other Lists'!$B$13:$G$15, 6, FALSE) -> 11 | S8: =Q8+R8 -> 28.8 | T8: =VLOOKUP(F8, 'Other Lists'!$B$13:$H$15, 7, FALSE) * M8 -> 31904 | U8: =S8*H8 -> 30240 | V8: =T8-U8 -> 1664 | W8: =(H8-M8) *P8 -> 1696 | X8: 6 | Y8: 0 | Z8: 3 | AA8: =X8-Y8-Z8-1 -> 2 | AB8: =VLOOKUP($AB$6, 'Other Lists'!$B$27:$H$32, 7, FALSE) *Y8*8 -> 0 | AC8: =VLOOKUP($AC$6, 'Other Lists'!$B$27:$H$32, 7, FALSE) * Z8 * 8 -> 842.4 | AD8: =VLOOKUP($AD$6, 'Other Lists'!$B$27:$H$32, 7, FALSE) * AA8 * 8 -> 518.4 | AE8: =SUM($AB$8:$AD$8) -> 1360.8 | AF8: =AE8/H8 -> 1.296 | AH8: 105 | AI8: 194 | AJ8: 194 | AK8: 0 | AL8: 216 | AM8: 0 | AN8: 0 | AO8: 180 | AP8: =AI8-AJ8 -> 0 | AQ8: =AO8/AJ8 -> 0.92783505 | AR8: =VLOOKUP($AH$8, 'Other Lists'!$B$13:$H$15, 7, FALSE) -> 184 | AS8: =VLOOKUP($AH$8, 'Other Lists'!$B$13:$F$15, 5, FALSE) -> 129 | AT8: =VLOOKUP($AH$8, 'Other Lists'!$B$13:$G$15, 6, FALSE) -> 36 | AU8: =AS8+AT8 -> 165 | AV8: =VLOOKUP($AH$84, 'Other Lists'!$B$13:$H$15, 7, FALSE) *AO8 -> 33120 | AW8: =AU8*AJ8 -> 32010 | AX8: =AV8-AW8 -> 1110 | AY8: =(AJ8-AO8)*AR8 -> 2576 | AZ8: 8 | BA8: 8 | BB8: 0 | BC8: 4 | BD8: =BA8-BB8-BC8-BK8 -> 2 | BE8: =VLOOKUP($BE$6, 'Other Lists'!$B$27:$H$32, 7, FALSE) *BB8*8 -> 0 | BF8: =VLOOKUP($BF$6, 'Other Lists'!$B$27:$H$32, 7, FALSE) * BC8 * 8 -> 1123.2 | BG8: =VLOOKUP($BG$6, 'Other Lists'!$B$27:$H$32, 7, FALSE) * BD8 * 8 -> 518.4 | BH8: =SUM($BE$8:$BG$8) -> 1641.6 | BI8: =BH8/AJ8 -> 8.4618557 | BK8: 2 | BL8: 2 | BM8: =VLOOKUP($BM$6, 'Other Lists'!$B$27:$H$32, 7, FALSE) * BK8 * 8 -> 648 | BN8: =VLOOKUP($BN$6, 'Other Lists'!$B$27:$H$32, 7, FALSE) * BL8 * 8 -> 648 | BO8: =SUM(BH8,BM8,BN8) -> 2937.6
B9: 161 | C9: 45324 | D9: =WEEKDAY(C9, 1) -> 6 | E9: 1 | F9: 201 | G9: 357 | H9: 357 | I9: 0 | J9: 420 | K9: 0 | L9: 0 | M9: 335 | N9: =G9-H9 -> 0 | O9: =M9/H9 -> 0.93837535 | P9: =VLOOKUP(F9, 'Other Lists'!$B$13:$H$154, 7, FALSE) -> 71 | Q9: =VLOOKUP(F9, 'Other Lists'!$B$13:$F$15, 5, FALSE) -> 32.6 | R9: =VLOOKUP(F9, 'Other Lists'!$B$13:$G$15, 6, FALSE) -> 16.5 | S9: =Q9+R9 -> 49.1 | T9: =VLOOKUP(F9, 'Other Lists'!$B$13:$H$15, 7, FALSE) * M9 -> 23785 | U9: =S9*H9 -> 17528.7 | V9: =T9-U9 -> 6256.3 | W9: =(H9-M9) *P9 -> 1562 | X9: 6 | Y9: 0 | Z9: 3 | AA9: =X9-Y9-Z9-1 -> 2 | AB9: =VLOOKUP($AB$6, 'Other Lists'!$B$27:$H$32, 7, FALSE) *Y9*8 -> 0 | AC9: =VLOOKUP($AC$6, 'Other Lists'!$B$27:$H$32, 7, FALSE) * Z9 * 8 -> 842.4 | AD9: =VLOOKUP($AD$6, 'Other Lists'!$B$27:$H$32, 7, FALSE) * AA9 * 8 -> 518.4 | AE9: =SUM($AB$8:$AD$8) -> 1360.8 | AF9: =AE9/H9 -> 3.8117647 | AH9: 105 | AI9: 213 | AJ9: 205 | AK9: 0 | AL9: 216 | AM9: 8 | AN9: 0 | AO9: 190 | AP9: =AI9-AJ9 -> 8 | AQ9: =AO9/AJ9 -> 0.92682927 | AR9: =VLOOKUP($AH$8, 'Other Lists'!$B$13:$H$15, 7, FALSE) -> 184 | AS9: =VLOOKUP($AH$8, 'Other Lists'!$B$13:$F$15, 5, FALSE) -> 129 | AT9: =VLOOKUP($AH$8, 'Other Lists'!$B$13:$G$15, 6, FALSE) -> 36 | AU9: =AS9+AT9 -> 165 | AV9: =VLOOKUP($AH$84, 'Other Lists'!$B$13:$H$15, 7, FALSE) *AO9 -> 34960 | AW9: =AU9*AJ9 -> 33825 | AX9: =AV9-AW9 -> 1135 | AY9: =(AJ9-AO9)*AR9 -> 2760 | AZ9: 8 | BA9: 8 | BB9: 0 | BC9: 4 | BD9: =BA9-BB9-BC9-BK9 -> 2 | BE9: =VLOOKUP($BE$6, 'Other Lists'!$B$27:$H$32, 7, FALSE) *BB9*8 -> 0 | BF9: =VLOOKUP($BF$6, 'Other Lists'!$B$27:$H$32, 7, FALSE) * BC9 * 8 -> 1123.2 | BG9: =VLOOKUP($BG$6, 'Other Lists'!$B$27:$H$32, 7, FALSE) * BD9 * 8 -> 518.4 | BH9: =SUM($BE$8:$BG$8) -> 1641.6 | BI9: =BH9/AJ9 -> 8.0078049 | BK9: 2 | BL9: 2 | BM9: =VLOOKUP($BM$6, 'Other Lists'!$B$27:$H$32, 7, FALSE) * BK9 * 8 -> 648 | BN9: =VLOOKUP($BN$6, 'Other Lists'!$B$27:$H$32, 7, FALSE) * BL9 * 8 -> 648 | BO9: =SUM(BH9,BM9,BN9) -> 2937.6
