Workbook

Sheet ReadMeFirst
A1: Read Me First
A3: This Excel Workbook was:
B4: Created by: | C4: Sakshi Salvi (he/him) Initials: SS
B5: Created for: | C5: Conestoga College BA Program, Courses INFO 8136 Case Study 1
B6: Created on: | C6: 45805
B7: Project: | C7: Case Study 1
B8: Possible Consumers of this: | C8: All Section Members of INFO8136
B9: Copyright: | C9: Conestoga College, 2024. All rights reserved
C10: Useage rights granted to registered section members of INFO 8136
A12: Assumptions:
A13: 1 | B13: None as of 2025 May 28
A15: Document History
A16: ID | B16: Updated by and on: | C16: Published on: | D16: Reason(s):
A17: 1 | B17: Sakshi Salvi | 28 May, 2025 | C17: 45805 | D17: Initial formatting of the document.
A18: 2 | B18: Sakshi Salvi | 12 June, 2025 | C18: 45820 | D18: Midpoint updates to deliverable, data elements, and interactions.
A19: 3 | B19: Sakshi Salvi | 18 June, 2025 | C19: 45826 | D19: Updates made to sheets: Data Involved, Actions, Risks, and Fishbone Diagram
A20: 4 | B20: Sakshi Salvi | 19 June, 2026 | C20: 45827 | D20: Fishbone diagram was updated.
A21: 5 | B21: Sakshi Salvi | 20 June, 2025 | C21: 45828 | D21: Finalization of all sheets, QC-reviewed.
A23: Sources and References
A24: 1 | B24: Case Study #1 Make a Plan. Ver 2.0
A25: 2 | B25: Various submitted questions from members of W24 Sections 1 and 5
A26: 3 | B26: INFO8136 Course Slides and Rubric
A27: 4 | B27: Interaction 3A Fishbone Reference Diagram (PDF from Prof. Bill Nixon, Jun 8, 2024)
A29: Sheets in this Workbook
A30: ID | B30: Sheet Name | C30: Description
A31: 1 | B31: ReadMeFirst | C31: Workbook overview, history, sources, structure
A32: 2 | B32: Deliverables | C32: Timeline, responsibilities, work records
A33: 3 | B33: Actors | C33: Roles, actor types, hardware/software assignments
A34: 4 | B34: Interactions | C34: Inspector actions, interface logic, input-output mapping
A35: 5 | B35: Tablet App | C35: Interface of the Tablet
A36: 7 | B36: Data Involved in Interactions | C36: Full list of fields (A–AC), metadata, and references
A37: 8 | B37: Actions | C37: Actions tied to each data element (e.g., Get, Enter, Retrieve)
A38: 9 | B38: Risks | C38: Risk descriptions, grouped categories (R1–R7), mitigation strategies
A39: 10 | B39: Fishbone Diagram | C39: Visual overview of the data elements and sources
B50: Start by Right-Clicking on the Text of the Sheet name.

Sheet Deliverables
A1: List of Deliverables | D1: Source: INFO8136 Case Study 1 and Associated Rubric | G1: Date: | H1: 45805 | J1: Author(s): | K1: SS
A3: Return to ReadMeFirst
B7: Deliverable ID | C7: Issue(s) | D7: Requirement(s) | E7: Deliverable Name | F7: Description | G7: Type | H7: Started Date | I7: Started Time | J7: Done Date | K7: Done Time | L7: QC OK Date | M7: QC OK Time | N7: Done By | O7: QC By
B8: D1 | C8: Unclear data flow | D8: List actors, actor types, systems | E8: Actors Table | F8: Detailed roles, hardware/software types, mapped to interaction | G8: Table | H8: 45807 | I8: 0.41666667 | J8: 45808 | K8: 0.45833333 | L8: 45826 | M8: 0.75 | N8: Sakshi Sandeep Salvi | O8: Instructor
B9: D2 | C9: No clear user interaction plan | D9: Map inspector actions to systems | E9: Interactions Sheet | F9: Includes trigger, input, outcome per interaction | G9: Table | H9: 45809 | I9: 0.39583333 | J9: 45810 | K9: 0.54166667 | L9: 45826 | M9: 0.75 | N9: Sakshi Sandeep Salvi | O9: Instructor
B10: D3 | C10: Weak field-level design | D10: Define A–AC structure with source, type | E10: Data Involved | F10: Fully defined data model with justification and references | G10: Data Model | H10: 45811 | I10: 0.45833333 | J10: 45813 | K10: 0.60416667 | L10: 45826 | M10: 0.75 | N10: Sakshi Sandeep Salvi | O10: Instructor
B11: D4 | C11: Incomplete action mapping | D11: Define verbs for each field | E11: Actions Table | F11: Maps all data elements to clock-in tasks | G11: Table | H11: 45814 | I11: 0.375 | J11: 45815 | K11: 0.5 | L11: 45826 | M11: 0.75 | N11: Sakshi Sandeep Salvi | O11: Instructor
B12: D5 | C12: Missing risk context | D12: Link each action to a grouped risk | E12: Risk Mapping Table | F12: Uses grouped risk categories (R1–R7) for clarity | G12: Risk Table | H12: 45816 | I12: 0.41666667 | J12: 45817 | K12: 0.5625 | L12: 45826 | M12: 0.75 | N12: Sakshi Sandeep Salvi | O12: Instructor
B13: D6 | C13: Lacking mitigation strategy | D13: Define detection, response, mitigation | E13: Risk Management Table | F13: Structured R1–R7 table with 3-part strategy | G13: Matrix Table | H13: 45818 | I13: 0.47916667 | J13: 45819 | K13: 0.625 | L13: 45826 | M13: 0.75 | N13: Sakshi Sandeep Salvi | O13: Instructor
B14: D7 | C14: Weak justification for fields | D14: Explain each data field’s purpose | E14: Data Involved - Justification and Relevance Column | F14: Covers all A–AC fields, split by justification and relevance | G14: Table | H14: 45820 | I14: 0.41666667 | J14: 45821 | K14: 0.5625 | L14: 45826 | M14: 0.75 | N14: Sakshi Sandeep Salvi | O14: Instructor
B15: D8 | C15: No framework to track login | D15: Develop visual diagram with key factors | E15: Fishbone Diagram | F15: Covers Inspector, Device, System, Location, Auth, Timing branches | G15: Diagram | H15: 45826 | I15: 0.375 | J15: 45827 | K15: 0.52083333 | L15: 45827 | M15: 0.70833333 | N15: Sakshi Sandeep Salvi | O15: Instructor
B16: D9 | C16: No strategic timeline | D16: Consolidate all components | E16: Final Submission Package | F16: Includes QC, naming, consistency, formatting, author signature | G16: Packaging | H16: 45826 | I16: 0.45833333 | J16: 45828 | K16: 0.58333333 | N16: Sakshi Sandeep Salvi

Sheet Actors
A1: LPQC Actors
B3: Note: LPQC = Little Panda Quality Control
B4: Note:TBI = To Be Inspected
I7: Actor Types List
A9: Actor ID | B9: Name | C9: Description | D9: Type | E9: Type Name | F9: RecordDate | G9: Source | I9: ID | J9: Actor Type
A10: A | B10: Jr Data Analyst | C10: each section member | D10: A | E10: =VLOOKUP(D10,$I$10:$J$21,2,FALSE) -> Role | I10: A | J10: Role
A11: B | B11: Sr Data Analyst | C11: Prof Bill | D11: A | E11: =VLOOKUP(D11,$I$10:$J$21,2,FALSE) -> Role | I11: B | J11: Computer Network
A12: C | B12: LPQC Computer Network | D12: B | E12: =VLOOKUP(D12,$I$10:$J$21,2,FALSE) -> Computer Network | I12: C | J12: DB Interface Hardware
A13: D | B13: LPQC Inspector App Tablet | D13: C | E13: =VLOOKUP(D13,$I$10:$J$21,2,FALSE) -> DB Interface Hardware | I13: D | J13: Business Process Objects
A14: E | B14: Parts TBI | C14: from manufacturers | D14: D | E14: =VLOOKUP(D14,$I$10:$J$21,2,FALSE) -> Business Process Objects | I14: E | J14: DB Tablet App
A15: F | B15: Inspected Parts - Found OK | D15: D | E15: =VLOOKUP(D15,$I$10:$J$21,2,FALSE) -> Business Process Objects | I15: F | J15: Business Data
A16: G | B16: Inspected Parts - Found NOT OK | D16: D | E16: =VLOOKUP(D16,$I$10:$J$21,2,FALSE) -> Business Process Objects | I16: G | J16: DB Tables
A17: H | B17: LPQC Inspector | D17: A | E17: =VLOOKUP(D17,$I$10:$J$21,2,FALSE) -> Role | I17: H | J17: DB Server with Database of Tables
A18: J | B18: LPQC Inspection Tablet App | D18: E | E18: =VLOOKUP(D18,$I$10:$J$21,2,FALSE) -> DB Tablet App | I18: J | J18: DB Workstation App
A19: K | B19: Parts Standards | C19: Part Element + Metric + Value + Acceptable Deviation | D19: F | E19: =VLOOKUP(D19,$I$10:$J$21,2,FALSE) -> Business Data | I19: K | J19: Work Area
A20: L | B20: Parts Standards Changes | C20: Received from Supplier | D20: F | E20: =VLOOKUP(D20,$I$10:$J$21,2,FALSE) -> Business Data | I20: L | J20: Computer workstations
A21: M | B21: Shipper / Receiver / Porter | D21: A | E21: =VLOOKUP(D21,$I$10:$J$21,2,FALSE) -> Role | I21: M | J21: Customer/Supplier
A22: N | B22: Day Inspections DB Tables | D22: G | E22: =VLOOKUP(D22,$I$10:$J$21,2,FALSE) -> DB Tables
A23: P | B23: Inspectors | D23: G | E23: =VLOOKUP(D23,$I$10:$J$21,2,FALSE) -> DB Tables
A24: Q | B24: Parts Standards Tables | D24: G | E24: =VLOOKUP(D24,$I$10:$J$21,2,FALSE) -> DB Tables
A25: R | B25: Inspection DB Server | D25: H | E25: =VLOOKUP(D25,$I$10:$J$21,2,FALSE) -> DB Server with Database of Tables
A26: S | B26: Parts Standards Interface | C26: only used in office | D26: J | E26: =VLOOKUP(D26,$I$10:$J$21,2,FALSE) -> DB Workstation App
A27: T | B27: Day Parts Received and Shipped | D27: J | E27: =VLOOKUP(D27,$I$10:$J$21,2,FALSE) -> DB Workstation App
A28: U | B28: Inspection Processes Manager | D28: A | E28: =VLOOKUP(D28,$I$10:$J$21,2,FALSE) -> Role
A29: V | B29: Day Inspections Managing | D29: J | E29: =VLOOKUP(D29,$I$10:$J$21,2,FALSE) -> DB Workstation App
A30: W | B30: Inspection Lines | D30: K | E30: =VLOOKUP(D30,$I$10:$J$21,2,FALSE) -> Work Area
A31: X | B31: Business Manager Workstations | D31: L | E31: =VLOOKUP(D31,$I$10:$J$21,2,FALSE) -> Computer workstations
A32: Y | B32: Parts Makers / Customers | D32: M | E32: =VLOOKUP(D32,$I$10:$J$21,2,FALSE) -> Customer/Supplier
L49: M | M49: =VLOOKUP(L49,$K$10:$L$21,2,FALSE) -> #N/A

Sheet Interactions
A1: LPQC Interactions | E1: ** This work is not final **
B4: *** See the Visio Diagram.
B7: ID | C7: Visio ID | E7: Interaction | F7: Description | G7: Actors Involved | H7: RecordDate | I7: Source
B9: 1 | C9: 1 | D9: a | E9: Record Received Parts TBI | F9: ="See Documentation Sec " &C9&D9 -> See Documentation Sec 1a
B10: 2 | C10: 1 | D10: b | E10: Receive Parts | F10: ="See Documentation Sec " &C10&D10 -> See Documentation Sec 1b
B11: 3 | C11: 1 | D11: c | E11: Deliver to Inspection Lines | F11: ="See Documentation Sec " &C11&D11 -> See Documentation Sec 1c
B12: 4 | C12: 2 | E12: Put Parts TBI on Day Inspection Schedule | F12: ="See Documentation Sec " &C12&D12 -> See Documentation Sec 2
B13: 5 | C13: 3 | D13: b | E13: Inspect parts. Record Data. | F13: ="See Documentation Sec " &C13&D13 -> See Documentation Sec 3b
B14: 6 | C14: 3 | D14: c | E14: Sort into Ok and Not OK. | F14: ="See Documentation Sec " &C14&D14 -> See Documentation Sec 3c
B15: 7 | C15: 4 | E15: Return OK parts to suppliers. | F15: ="See Documentation Sec " &C15&D15 -> See Documentation Sec 4
B16: 8 | C16: 5 | E16: Send NOT OK parts to ????. | F16: ="See Documentation Sec " &C16&D16 -> See Documentation Sec 5
B17: 9 | C17: 6 | D17: a | E17: Inspectors Clock IN | F17: ="See Documentation Sec " &C17&D17 -> See Documentation Sec 6a
B18: 10 | C18: 6 | D18: b | E18: Inspectors Clock Out | F18: ="See Documentation Sec " &C18&D18 -> See Documentation Sec 6b
B19: 11 | C19: 6 | D19: c | E19: Inspectors Log IN | F19: ="See Documentation Sec " &C19&D19 -> See Documentation Sec 6c
B20: 12 | C20: 6 | D20: d | E20: Inspectors Log Out. | F20: ="See Documentation Sec " &C20&D20 -> See Documentation Sec 6d
B21: 13 | C21: 6 | D21: e | E21: Inspectors Get Tablet | F21: ="See Documentation Sec " &C21&D21 -> See Documentation Sec 6e
B22: 14 | C22: 6 | D22: f | E22: Inspectors Return Tablet | F22: ="See Documentation Sec " &C22&D22 -> See Documentation Sec 6f
B23: 15 | C23: 7 | D23: a | E23: Manage New Sets of Parts Standards Data. | F23: ="See Documentation Sec " &C23&D23 -> See Documentation Sec 7a
B24: 16 | C24: 7 | D24: b | E24: Update changes to Already Loaded Parts Data Sets | F24: ="See Documentation Sec " &C24&D24 -> See Documentation Sec 7b

Sheet Tablet App
A1: LPQI Tablet App Interface

Sheet Data Involved
A1: LPQI Data Involved for Interaction 6A
B7: ID | C7: Interaction | D7: Interaction Name / Unit of Work | E7: Interface Used | F7: DB Table | G7: Data Element | H7: Data Type | I7: Data Scope | J7: Data Source | K7: Justification | L7: Relevance
B8: 1 | C8: 6A | D8: Inspectors Clock IN | E8: Inspector's Tablet / Clock In App | F8: Clock In Master Table | G8: ClockInID | H8: INT | I8: Primary Key | J8: Auto Assigned by the LPQI DB Server | K8: Uniquely identifies each clock-in event | L8: Supports traceability and audit trail.
B9: 2 | C9: 6A | D9: Inspectors Clock IN | E9: Inspector's Tablet / Clock In App | F9: Clock In Master Table | G9: InspectorID | H9: VARCHAR(10) | I9: Foreign Key | J9: Inspector Master Table | K9: Associates entry with a specific user | L9: Ensures accountability and validation.
B10: 3 | C10: 6A | D10: Inspectors Clock IN | E10: Inspector's Tablet / Clock In App | F10: Clock In Master Table | G10: DeviceID | H10: VARCHAR(15) | I10: Foreign Key | J10: Device Master Table | K10: Identifies the login device used | L10: Helps detect unauthorized access.
B11: 4 | C11: 6A | D11: Inspectors Clock IN | E11: Inspector's Tablet / Clock In App | F11: Clock In Master Table | G11: SessionID | H11: VARCHAR(12) | I11: - | J11: System | K11: Connects actions within one session | L11: Useful for debugging session activity.
B12: 5 | C12: 6A | D12: Inspectors Clock IN | E12: Inspector's Tablet / Clock In App | F12: Clock In Master Table | G12: RecordCreateDate | H12: DATE | I12: - | J12: System Timestamp | K12: Stores the creation date of the record | L12: Tracks data lifecycle.
B13: 6 | C13: 6A | D13: Inspectors Clock IN | E13: Inspector's Tablet / Clock In App | F13: Clock In Master Table | G13: RecordCreateTime | H13: TIME | I13: - | J13: System Timestamp | K13: Captures exact creation time | L13: Aids in audit logging and analysis.
B14: 7 | C14: 6A | D14: Inspectors Clock IN | E14: Inspector's Tablet / Clock In App | F14: Clock In Master Table | G14: RecordExpireDate | H14: DATE(NULLABLE) | I14: - | J14: System | K14: Date when record expires | L14: Helps schedule clean-up/archive operations.
B15: 8 | C15: 6A | D15: Inspectors Clock IN | E15: Inspector's Tablet / Clock In App | F15: Clock In Master Table | G15: RecordExpireTime | H15: TIME(NULLABLE) | I15: - | J15: System | K15: Time when record expires | L15: Completes precise expiration timestamp.
B16: 9 | C16: 6A | D16: Inspectors Clock IN | E16: Inspector's Tablet / Clock In App | F16: Clock In Master Table | G16: ClockInDate | H16: DATE | I16: - | J16: Clock In App | K16: Shows when shift began | L16: Used in attendance and shift calculations.
B17: 10 | C17: 6A | D17: Inspectors Clock IN | E17: Inspector's Tablet / Clock In App | F17: Clock In Master Table | G17: ClockInTime | H17: TIME | I17: - | J17: Clock In App | K17: Logs exact clock-in time | L17: Used to calculate lateness and payroll.
B18: 11 | C18: 6A | D18: Inspectors Clock IN | E18: Inspector's Tablet / Clock In App | F18: Clock In Master Table | G18: ClockOutDate | H18: DATE | I18: - | J18: Clock In App | K18: Captures end-of-shift date | L18: Enables full-day time span tracking.
B19: 12 | C19: 6A | D19: Inspectors Clock IN | E19: Inspector's Tablet / Clock In App | F19: Clock In Master Table | G19: ClockOutTime | H19: TIME | I19: - | J19: Clock In App | K19: Logs end-of-shift time | L19: Completes work duration data.
... B36: 29 | C36: 6A | D36: Inspectors Clock IN | E36: Inspector's Tablet / Clock In App | F36: HR Attendance Table | G36: AttendanceFlag | H36: BOOLEAN | I36: - | J36: HR Table | K36: Indicates successful attendance | L36: Used by HR/payroll systems.

Sheet Actions
B3: Actions for: | D3: ='Data Involved'!D8 -> Inspectors Clock IN
B5: Interface Used: | D5: ='Data Involved'!E8 -> Inspector's Tablet / Clock In App
B7: Assumptions: | D7: 1) The inspector must clock in using their personal ID and password through a secure app on the tablet or workstation. Clock-in may occur at any valid terminal within the facility.
D8: 2) Identity must be confirmed using verification mechanisms such as a swipe card, badge tap, or fob. The system must check credentials before registering the shift start time.
B13: ID | D13: Data Element | F13: Data Source
B14: A | C14: Get | D14: ='Data Involved'!G8 -> ClockInID | E14: from | F14: ='Data Involved'!J8 -> Auto Assigned by the LPQI DB Server
B15: B | C15: Get | D15: ='Data Involved'!G9 -> InspectorID | E15: from | F15: ='Data Involved'!J9 -> Inspector Master Table
B16: C | C16: Get | D16: ='Data Involved'!G10 -> DeviceID | E16: from | F16: ='Data Involved'!J10 -> Device Master Table
B17: D | C17: Get | D17: ='Data Involved'!G11 -> SessionID | E17: from | F17: ='Data Involved'!J11 -> System
B18: E | C18: Get | D18: ='Data Involved'!G12 -> RecordCreateDate | E18: from | F18: ='Data Involved'!J12 -> System Timestamp
B19: F | C19: Get | D19: ='Data Involved'!G13 -> RecordCreateTime | E19: from | F19: ='Data Involved'!J13 -> System Timestamp
B20: G | C20: Get | D20: ='Data Involved'!G14 -> RecordExpireDate | E20: from | F20: ='Data Involved'!J14 -> System
B21: H | C21: Get | D21: ='Data Involved'!G15 -> RecordExpireTime | E21: from | F21: ='Data Involved'!J15 -> System
B22: I | C22: Get | D22: ='Data Involved'!G16 -> ClockInDate | E22: from | F22: ='Data Involved'!J16 -> Clock In App | H22: Risks for: | I22: =D3 & " Actions" -> Inspectors Clock IN Actions
B23: J | C23: Get | D23: ='Data Involved'!G17 -> ClockInTime | E23: from | F23: ='Data Involved'!J17 -> Clock In App
B24: K | C24: Get | D24: ='Data Involved'!G18 -> ClockOutDate | E24: from | F24: ='Data Involved'!J18 -> Clock In App | H24: Interface Used:
B25: L | C25: Get | D25: ='Data Involved'!G19 -> ClockOutTime | E25: from | F25: ='Data Involved'!J19 -> Clock In App | I25: =D5 -> Inspector's Tablet / Clock In App | J25: Risk = What could go wrong?
B26: M | C26: Get | D26: ='Data Involved'!G20 -> ClockInType | E26: from | F26: ='Data Involved'!J20 -> Clock In App | H26: Actors Involved | J26: You must create the risks!
B27: N | C27: Get | D27: ='Data Involved'!G21 -> ClockInStatus | E27: from | F27: ='Data Involved'!J21 -> Clock In App | I27: N Inspector, Part to be Inspected | J27: Below are only samples!
B28: O | C28: Get | D28: ='Data Involved'!G22 -> ClockInFailureReason | E28: from | F28: ='Data Involved'!J22 -> Clock In App
B29: P | C29: Get | D29: ='Data Involved'!G23 -> RetryFlag | E29: from | F29: ='Data Involved'!J23 -> Clock In App | H29: =B13 -> ID | I29: Action | J29: Risk
B30: Q | C30: Get | D30: ='Data Involved'!G24 -> ClockInVerificationID | E30: from | F30: ='Data Involved'!J24 -> Verification Logs | H30: A | I30: =C14&" "&D14&" "&E14&" "&F14 -> Get ClockInID from Auto Assigned by the LPQI DB Server | J30: R4: System Failures
B31: R | C31: Get | D31: ='Data Involved'!G25 -> VerificationMethod | E31: from | F31: ='Data Involved'!J25 -> Clock In App | H31: B | I31: =C15&" "&D15&" "&E15&" "&F15 -> Get InspectorID from Inspector Master Table | J31: R1: Invalid/Missing Data
B32: S | C32: Get | D32: ='Data Involved'!G26 -> VerificationDeviceType | E32: from | F32: ='Data Involved'!J26 -> Clock In App | H32: C | I32: =C16&" "&D16&" "&E16&" "&F16 -> Get DeviceID from Device Master Table | J32: R3: Device/Location Issues
B33: T | C33: Get | D33: ='Data Involved'!G27 -> LoginLocation | E33: from | F33: ='Data Involved'!J27 -> Location Master Table | H33: D | I33: =C17&" "&D17&" "&E17&" "&F17 -> Get SessionID from System | J33: R4: System Failures
B34: U | C34: Get | D34: ='Data Involved'!G28 -> WorkAction | E34: from | F34: ='Data Involved'!J28 -> Clock In App | H34: E | I34: =C18&" "&D18&" "&E18&" "&F18 -> Get RecordCreateDate from System Timestamp | J34: R4: System Failures
B35: V | C35: Get | D35: ='Data Involved'!G29 -> ClockInReason | E35: from | F35: ='Data Involved'!J29 -> Clock In App | H35: F | I35: =C19&" "&D19&" "&E19&" "&F19 -> Get RecordCreateTime from System Timestamp | J35: R4: System Failures
B36: W | C36: Get | D36: ='Data Involved'!G30 -> VerificationFlag | E36: from | F36: ='Data Involved'!J30 -> Authentication System | H36: G | I36: =C20&" "&D20&" "&E20&" "&F20 -> Get RecordExpireDate from System | J36: R1: Invalid/Missing Data
B37: X | C37: Get | D37: ='Data Involved'!G31 -> InspectorBadgeID | E37: from | F37: ='Data Involved'!J31 -> Badge System | H37: H | I37: =C21&" "&D21&" "&E21&" "&F21 -> Get RecordExpireTime from System | J37: R1: Invalid/Missing Data
B38: Y | C38: Get | D38: ='Data Involved'!G32 -> PasswordEntered | E38: from | F38: ='Data Involved'!J32 -> Clock In App | H38: I | I38: =C22&" "&D22&" "&E22&" "&F22 -> Get ClockInDate from Clock In App | J38: R1: Invalid/Missing Data
B39: Z | C39: Get | D39: ='Data Involved'!G33 -> DeviceTrusted | E39: from | F39: ='Data Involved'!J33 -> Device Config | H39: J | I39: =C23&" "&D23&" "&E23&" "&F23 -> Get ClockInTime from Clock In App | J39: R5: User Errors
B40: AA | C40: Get | D40: ='Data Involved'!G34 -> ActiveSessionID | E40: from | F40: ='Data Involved'!J34 -> Session Logs | H40: K | I40: =C24&" "&D24&" "&E24&" "&F24 -> Get ClockOutDate from Clock In App | J40: R5: User Errors
B41: AB | C41: Get | D41: ='Data Involved'!G35 -> InspectorLogStatus | E41: from | F41: ='Data Involved'!J35 -> Clock In App | H41: L | I41: =C25&" "&D25&" "&E25&" "&F25 -> Get ClockOutTime from Clock In App | J41: R5: User Errors
B42: AC | C42: Get | D42: ='Data Involved'!G36 -> AttendanceFlag | E42: from | F42: ='Data Involved'!J36 -> HR Table | H42: M | I42: =C26&" "&D26&" "&E26&" "&F26 -> Get ClockInType from Clock In App | J42: R5: User Errors
H43: N | I43: =C27&" "&D27&" "&E27&" "&F27 -> Get ClockInStatus from Clock In App | J43: R4: System Failures
H44: O | I44: =C28&" "&D28&" "&E28&" "&F28 -> Get ClockInFailureReason from Clock In App | J44: R1: Invalid/Missing Data
H45: P | I45: =C29&" "&D29&" "&E29&" "&F29 -> Get RetryFlag from Clock In App | J45: R4: System Failures
H46: Q | I46: =C30&" "&D30&" "&E30&" "&F30 -> Get ClockInVerificationID from Verification Logs | J46: R6: Audit & Security Gaps
H47: R | I47: =C31&" "&D31&" "&E31&" "&F31 -> Get VerificationMethod from Clock In App | J47: R2: Authentication Failures
H48: S | I48: =C32&" "&D32&" "&E32&" "&F32 -> Get VerificationDeviceType from Clock In App | J48: R3: Device/Location Issues
...

Sheet Risks
A1: Risk Details
A3: SR. No | B3: Risk Name | C3: Risk Description | D3: Risk Detection | E3: Risk Response | F3: Risk Mitigate
A4: R1 | B4: Invalid / Missing Data | C4: Fields such as dates, reasons, or IDs are blank, wrongly entered, or not recorded at all. | D4: System validates required fields before submission. | E4: Block submission and prompt user to complete missing data. | F4: Enforce mandatory fields, dropdowns, and pre-filled values.
A5: R2 | B5: Authentication Failures | C5: Passwords or verification methods are incorrect or bypassed. | D5: Track failed login attempts and invalid credentials. | E5: Alert user and restrict access after multiple failures. | F5: Use 2 Factor Authentication, strong password rules, and login logging.
A6: R3 | B6: Device / Location Issues | C6: Clock-in attempts from unauthorized devices or locations. | D6: Log device ID and GPS/location at login. | E6: Block login from unverified sources; send alert. | F6: Whitelist devices and IPs, apply geofencing policies.
A7: R4 | B7: System Failures | C7: Timeouts, duplicate IDs, or system lag causes disruption. | D7: Log backend failures and retry events. | E7: Retry request or route to admin interface. | F7: Use reliable ID generation and synchronized system clocks.
A8: R5 | B8: User Errors | C8: Users forget to clock out, choose wrong options, or input wrong times. | D8: Check session duration and clock-in/out sequence logic. | E8: Auto-correct or flag suspicious patterns for review. | F8: Provide dropdowns, reminders, and session-based validations.
A9: R6 | B9: Audit & Security Gaps | C9: Logs missing, badges cloned, or statuses not updated. | D9: Monitor log integrity and session activity reports. | E9: Raise flag if log/session data is inconsistent. | F9: Tag devices uniquely, log all critical actions, auto-refresh statuses.
A10: R7 | B10: HR Record Errors | C10: Attendance not updated correctly in HR tables. | D10: Compare clock-in data with HR attendance records daily. | E10: Alert HR admin or auto-sync data post-session. | F10: Add end-of-day or session-based sync scripts with fallback alerts.

Sheet Fishbone Diagram
